Workbook

Sheet How to update dates
A1: 1. About half way through earnings season export a new files from ToS
A2: 2. Only update future dates, so paste the formula into the next earnings and copy that down.
A3: 3. Paste values and switch format to full year using the little icon that pops up.
A4: 4. Now, sort oldest to newest.
A5: 5. By doing this all past sorting by date will stay the same, but, future dates will be adjusted to be accurate.

Sheet Indices
A1: Stock | B1: Index | C1: Index2 | D1: Sector | E1: As of: | F1: 45616
A2: NVDA | B2: SP500 | C2: NQ100
A3: AAPL | B3: SP500 | C3: NQ100
A4: MSFT | B4: SP500 | C4: NQ100
A5: GOOG | B5: SP500 | C5: NQ100
A6: GOOGL | B6: SP500 | C6: NQ100
A7: AMZN | B7: SP500 | C7: NQ100
A8: META | B8: SP500 | C8: NQ100
A9: TSLA | B9: SP500 | C9: NQ100
A10: BRK.B | B10: SP500
A11: AVGO | B11: SP500 | C11: NQ100
A12: WMT | B12: SP500
A13: JPM | B13: SP500
A14: LLY | B14: SP500
A15: V | B15: SP500
A16: UNH | B16: SP500
A17: XOM | B17: SP500
A18: ORCL | B18: SP500
A19: MA | B19: SP500
A20: COST | B20: SP500 | C20: NQ100
A21: PG | B21: SP500
A22: HD | B22: SP500
A23: NFLX | B23: SP500 | C23: NQ100
A24: JNJ | B24: SP500
A25: BAC | B25: SP500
A26: CRM | B26: SP500
A27: ABBV | B27: SP500
A28: CVX | B28: SP500
A29: TMUS | B29: SP500 | C29: NQ100
A30: KO | B30: SP500
A31: MRK | B31: SP500
A32: WFC | B32: SP500
A33: CSCO | B33: SP500 | C33: NQ100
A34: BX | B34: SP500
A35: ACN | B35: SP500
A36: AMD | B36: SP500 | C36: NQ100
A37: ADBE | B37: SP500 | C37: NQ100
A38: PEP | B38: SP500 | C38: NQ100
A39: LIN | B39: SP500 | C39: NQ100
A40: MS | B40: SP500
...

Sheet Pivot
A1: Index | B1: (Multiple Items)
A3: Row Labels | B3: Count of Ticker
A4: 7-Jan | B4: 1
A5: 8-Jan | B5: 3
A6: 10-Jan | B6: 4
A7: 14-Jan | B7: 5
A8: 15-Jan | B8: 5
A9: 16-Jan | B9: 9
A10: 17-Jan | B10: 6
A11: 21-Jan | B11: 15
A12: 22-Jan | B12: 22
A13: 23-Jan | B13: 13
A14: 24-Jan | B14: 3
A15: 27-Jan | B15: 10
... A61: Grand Total | B61: 843

Sheet Sector Summary
A1: 2025 -- Q1
A3: Executive Summary:
A4: =_xlfn.CONCAT(" For the ",A1," earnings season, ", TEXT('Stats Roll Up'!R4,"###")& " earnings trades were taken, ",TEXT('Summary Data'!B2,"00%")," were stocks from the S&P 500.") -> For the 2025 -- Q1 earnings season, 443 earnings trades were taken, 88% were stocks from the S&P 500.
A5: ● | B5: =CONCATENATE("Overall, the The Earnings Strategy producted: ") -> Overall, the The Earnings Strategy producted: | O5: =TEXT('Summary Data'!J$4,"0.0") -> 68.6 | Q5: risk units.
A6: Up Trending Stocks:
A7: ● | B7: =_xlfn.CONCAT('Summary Data'!$D$2," of the trades were stocks in an up trend."," This is ", TEXT('Summary Data'!$E$2,"00%")," of all trades.") -> 101 of the trades were stocks in an up trend. This is 23% of all trades.
A8: ● | B8: =_xlfn.CONCAT(TEXT('Stats Roll Up'!$G$4,"00.0%")," of the up trendng stocks opened higher after earnings. The average gap higher was ",TEXT('Stats Roll Up'!$D$4,"0.0%"),".") -> 52.5% of the up trendng stocks opened higher after earnings. The average gap higher was 5.0%.
A9: ● | B9: =_xlfn.CONCAT(TEXT('Stats Roll Up'!$AC$4,"00.0%")," of the up trendng stocks opened lower after earnings. The average gap down from an up trend was ",TEXT('Stats Roll Up'!$AE$4,"0.0%"),".") -> 47.5% of the up trendng stocks opened lower after earnings. The average gap down from an up trend was 4.6%.
A10: ● | B10: =CONCATENATE("For up trends, the strategy produced: ") -> For up trends, the strategy produced: | M10: ='Summary Data'!$D$4 -> 10.009379 | N10: risk units.
A11: ● | B11: Up trends had an expectancy of: | K11: =Expectancy!$Q$3 -> 0.099102767 | M11: risk units per trade.
A13: Down Trending Stocks:
A14: ● | B14: =_xlfn.CONCAT('Summary Data'!$F$2," of the trades were stocks in an down trend."," This is ", TEXT('Summary Data'!$G$2,"00%")," of all trades.") -> 128 of the trades were stocks in an down trend. This is 29% of all trades.
A15: ● | B15: =_xlfn.CONCAT(TEXT('Stats Roll Up'!$Y$4,"00.0%")," of the down trending stocks opened lower after earnings. The average gap down was ",TEXT('Stats Roll Up'!$AA$4,"0.0%"),".") -> 59.4% of the down trending stocks opened lower after earnings. The average gap down was 6.5%.
A16: ● | B16: =_xlfn.CONCAT(TEXT('Stats Roll Up'!$K$4,"00.0%")," of the down trending stocks opened higher after earnings. The average gap up from a down trend was ",TEXT('Stats Roll Up'!$M$4,"0.0%"),".") -> 40.6% of the down trending stocks opened higher after earnings. The average gap up from a down trend was 4.6%.
A17: ● | B17: =CONCATENATE("For down trends, the strategy produced: ") -> For down trends, the strategy produced: | N17: ='Summary Data'!$F$4 -> 43.496895 | O17: =_xlfn.CONCAT("risk units.") -> risk units.
A18: ● | B18: Down trends had an expectancy of: | L18: =Expectancy!$R$3 -> 0.33981949 | N18: risk units per trade.
A20: Sideways Trending Stocks:
A21: ● | B21: =_xlfn.CONCAT('Summary Data'!$H$2," of the trades were stocks in a sideways trend."," This is ", TEXT('Summary Data'!$I$2,"00%")," of all trades.") -> 215 of the trades were stocks in a sideways trend. This is 48% of all trades.
A22: ● | B22: =_xlfn.CONCAT(TEXT('Stats Roll Up'!$O$4,"00.0%")," of the sideways stocks opened higher after earnings. The average gap up was ",TEXT('Stats Roll Up'!$Q$4,"0.0%"),".") -> 51.2% of the sideways stocks opened higher after earnings. The average gap up was 5.0%.
A23: ● | B23: =_xlfn.CONCAT(TEXT('Stats Roll Up'!$AG$4,"00.0%")," of the sideways stocks opened lower after earnings. The average gap down from a sideways trend was ",TEXT('Stats Roll Up'!$AI$4,"0.0%"),".") -> 48.8% of the sideways stocks opened lower after earnings. The average gap down from a sideways trend was 4.4%.
A24: ● | B24: =CONCATENATE("For sideways trends, the strategy produced: ") -> For sideways trends, the strategy produced: | N24: ='Summary Data'!$H$4 -> 15.126535 | O24: =_xlfn.CONCAT("risk units.") -> risk units.
A25: ● | B25: Sideways trends had an expectancy of: | M25: =Expectancy!$S$3 -> 0.070355978 | O25: risk units per trade.
A40: 2025 -- Q1
A42: Sector Performance:
A43: Up Trending Stocks, Risk Units by Sector:
A57: Down Trending Stocks, Risk Units by Sector:
A71: Sideways Trending Stocks:
A85: 2025 -- Q1
A87: Sector Performance, continued:
A88: Total Risk Units by Sector, w/ Expectancy:

Sheet Summary Data
B1: % in SPY | C1: Total | D1: # in Up | E1: % in Up | F1: # in Dwn | G1: % in Dwn | H1: # in SW | I1: % in SW
B2: =COUNTIF('2025-Q1'!$D$4:$D$448,"Y")/C2 -> 0.87640449 | C2: =COUNTA('2025-Q1'!$D$4:$D$448) -> 445 | D2: =COUNTIF('2025-Q1'!$FV$4:$FV$448,"Up") -> 101 | E2: =D2/$C$2 -> 0.22696629 | F2: =COUNTIF('2025-Q1'!$FV$4:$FV$448,"Dwn") -> 128 | G2: =F2/$C$2 -> 0.28764045 | H2: =COUNTIF('2025-Q1'!$FV$4:$FV$448,"Sw") -> 215 | I2: =H2/$C$2 -> 0.48314607
D3: Up: R | F3: Down: R | H3: SW: R | J3: All: R
D4: =SUM('2025-Q1'!$T$4:$T$448) -> 10.009379 | F4: =SUM('2025-Q1'!$V$4:$V$448) -> 43.496895 | H4: =SUM('2025-Q1'!$X$4:$X$448) -> 15.126535 | J4: =D4+F4+H4 -> 68.632809
B8: Risk Units | C8: Expectancy
A9: Up | B9: =D4 -> 10.009379 | C9: =Expectancy!Q3 -> 0.099102767
A10: Down | B10: =F4 -> 43.496895 | C10: =Expectancy!R3 -> 0.33981949
A11: SW | B11: =H4 -> 15.126535 | C11: =Expectancy!S3 -> 0.070355978

Sheet Earnings
A1: Date/Time | B1: Ticker | C1: When | D1: Index
A2: 45659.587 | B2: LFCR | C2: on 1/2/25, 4:05 PM After Market Eastern Standard Time | D2: =_xlfn.XLOOKUP(B2,Indices!$A$2:$A$2676,Indices!$B$2:$B$2676,"")
A3: 45659.59 | B3: RGP | C3: on 1/2/25, 4:10 PM After Market Eastern Standard Time | D3: =_xlfn.XLOOKUP(B3,Indices!$A$2:$A$2676,Indices!$B$2:$B$2676,"") -> IWM
A4: 45660.25 | B4: EMKR | C4: on 1/3/25, 8:00 AM Before Market Eastern Standard Time | D4: =_xlfn.XLOOKUP(B4,Indices!$A$2:$A$2676,Indices!$B$2:$B$2676,"")
A5: 45663.463 | B5: CMC | C5: on 1/6/25, 1:06 PM During Market Eastern Standard Time | D5: =_xlfn.XLOOKUP(B5,Indices!$A$2:$A$2676,Indices!$B$2:$B$2676,"") -> IWM
A6: 45664.188 | B6: APOG | C6: on 1/7/25, 6:30 AM Before Market Eastern Standard Time | D6: =_xlfn.XLOOKUP(B6,Indices!$A$2:$A$2676,Indices!$B$2:$B$2676,"") -> IWM
A7: 45664.198 | B7: LNN | C7: on 1/7/25, 6:45 AM Before Market Eastern Standard Time | D7: =_xlfn.XLOOKUP(B7,Indices!$A$2:$A$2676,Indices!$B$2:$B$2676,"") -> IWM
A8: 45664.198 | B8: RPM | C8: on 1/7/25, 6:45 AM Before Market Eastern Standard Time | D8: =_xlfn.XLOOKUP(B8,Indices!$A$2:$A$2676,Indices!$B$2:$B$2676,"") -> S&P Mid
A9: 45664.587 | B9: CALM | C9: on 1/7/25, 4:05 PM After Market Eastern Standard Time | D9: =_xlfn.XLOOKUP(B9,Indices!$A$2:$A$2676,Indices!$B$2:$B$2676,"") -> IWM
A10: 45664.587 | B10: AIR | C10: on 1/7/25, 4:05 PM After Market Eastern Standard Time | D10: =_xlfn.XLOOKUP(B10,Indices!$A$2:$A$2676,Indices!$B$2:$B$2676,"") -> IWM
A11: 45664.587 | B11: KRUS | C11: on 1/7/25, 4:05 PM After Market Eastern Standard Time | D11: =_xlfn.XLOOKUP(B11,Indices!$A$2:$A$2676,Indices!$B$2:$B$2676,"") -> IWM
A12: 45664.588 | B12: SLP | C12: on 1/7/25, 4:06 PM After Market Eastern Standard Time | D12: =_xlfn.XLOOKUP(B12,Indices!$A$2:$A$2676,Indices!$B$2:$B$2676,"") -> IWM
A13: 45664.594 | B13: AZZ | C13: on 1/7/25, 4:15 PM After Market Eastern Standard Time | D13: =_xlfn.XLOOKUP(B13,Indices!$A$2:$A$2676,Indices!$B$2:$B$2676,"") -> IWM
... A1924: 45706.594 | B1924: ESI | C1924: on 2/18/25, 4:15 PM After Market Eastern Standard Time | D1924: =_xlfn.XLOOKUP(B1924,Indices!$A$2:$A$2676,Indices!$B$2:$B$2676,"")
A1925: 45706.596 | B1925: TRUE | C1925: on 2/18/25, 4:18 PM After Market Eastern Standard Time | D1925: =_xlfn.XLOOKUP(B1925,Indices!$A$2:$A$2676,Indices!$B$2:$B$2676,"")
A1926: 45706.597 | B1926: CE | C1926: on 2/18/25, 4:20 PM After Market Eastern Standard Time | D1926: =_xlfn.XLOOKUP(B1926,Indices!$A$2:$A$2676,Indices!$B$2:$B$2676,"") -> SP500
A1927: 45706.599 | B1927: OXY | C1927: on 2/18/25, 4:22 PM After Market Eastern Standard Time | D1927: =_xlfn.XLOOKUP(B1927,Indices!$A$2:$A$2676,Indices!$B$2:$B$2676,"") -> SP500
A1928: 45706.599 | B1928: STHO | C1928: on 2/18/25, 4:22 PM After Market Eastern Standard Time | D1928: =_xlfn.XLOOKUP(B1928,Indices!$A$2:$A$2676,Indices!$B$2:$B$2676,"")
A1929: 45706.599 | B1929: MTDR | C1929: on 2/18/25, 4:23 PM After Market Eastern Standard Time | D1929: =_xlfn.XLOOKUP(B1929,Indices!$A$2:$A$2676,Indices!$B$2:$B$2676,"") -> S&P Mid
A1930: 45706.601 | B1930: SEVN | C1930: on 2/18/25, 4:25 PM After Market Eastern Standard Time | D1930: =_xlfn.XLOOKUP(B1930,Indices!$A$2:$A$2676,Indices!$B$2:$B$2676,"")
A1931: 45706.604 | B1931: CHCT | C1931: on 2/18/25, 4:30 PM After Market Eastern Standard Time | D1931: =_xlfn.XLOOKUP(B1931,Indices!$A$2:$A$2676,Indices!$B$2:$B$2676,"") -> IWM
A1932: 45706.604 | B1932: EQT | C1932: on 2/18/25, 4:30 PM After Market Eastern Standard Time | D1932: =_xlfn.XLOOKUP(B1932,Indices!$A$2:$A$2676,Indices!$B$2:$B$2676,"") -> SP500
A1933: 45706.604 | B1933: UIS | C1933: on 2/18/25, 4:30 PM After Market Eastern Standard Time | D1933: =_xlfn.XLOOKUP(B1933,Indices!$A$2:$A$2676,Indices!$B$2:$B$2676,"") -> IWM
A1934: 45706.604 | B1934: CSR | C1934: on 2/18/25, 4:30 PM After Market Eastern Standard Time | D1934: =_xlfn.XLOOKUP(B1934,Indices!$A$2:$A$2676,Indices!$B$2:$B$2676,"") -> IWM
A1935: 45706.604 | B1935: SON | C1935: on 2/18/25, 4:30 PM After Market Eastern Standard Time | D1935: =_xlfn.XLOOKUP(B1935,Indices!$A$2:$A$2676,Indices!$B$2:$B$2676,"") -> S&P Mid
A1936: 45706.604 | B1936: TOL | C1936: on 2/18/25, 4:30 PM After Market Eastern Standard Time | D1936: =_xlfn.XLOOKUP(B1936,Indices!$A$2:$A$2676,Indices!$B$2:$B$2676,"") -> S&P Mid
A1937: 45706.609 | B1937: XP | C1937: on 2/18/25, 4:37 PM After Market Eastern Standard Time | D1937: =_xlfn.XLOOKUP(B1937,Indices!$A$2:$A$2676,Indices!$B$2:$B$2676,"")
... A2791: 45714.596 | B2791: KW | C2791: on 2/26/25, 4:18 PM After Market Eastern Standard Time | D2791: =_xlfn.XLOOKUP(B2791,Indices!$A$2:$A$2676,Indices!$B$2:$B$2676,"") -> IWM
A2792: 45714.597 | B2792: FE | C2792: on 2/26/25, 4:20 PM After Market Eastern Standard Time | D2792: =_xlfn.XLOOKUP(B2792,Indices!$A$2:$A$2676,Indices!$B$2:$B$2676,"") -> SP500 | E2792: =_xlfn.XLOOKUP(B2792,'2025-Q1'!$A$402:$A$448,'2025-Q1'!$A$402:$A$448,"avail") -> avail | F2792: =_xlfn.XLOOKUP(B2792,'[2]!! -- Stock Universe 12.11.24'!$C$2:$C$1621,'[2]!! -- Stock Universe 12.11.24'!$E$2:$E$1621,"")
A2793: 45714.597 | B2793: NVDA | C2793: on 2/26/25, 4:20 PM After Market Eastern Standard Time | D2793: =_xlfn.XLOOKUP(B2793,Indices!$A$2:$A$2676,Indices!$B$2:$B$2676,"") -> SP500 | E2793: =_xlfn.XLOOKUP(B2793,'2025-Q1'!$A$402:$A$448,'2025-Q1'!$A$402:$A$448,"avail") -> avail | F2793: =_xlfn.XLOOKUP(B2793,'[2]!! -- Stock Universe 12.11.24'!$C$2:$C$1621,'[2]!! -- Stock Universe 12.11.24'!$E$2:$E$1621,"") -> Technology
A2794: 45714.597 | B2794: SVC | C2794: on 2/26/25, 4:20 PM After Market Eastern Standard Time | D2794: =_xlfn.XLOOKUP(B2794,Indices!$A$2:$A$2676,Indices!$B$2:$B$2676,"") -> IWM | E2794: =_xlfn.XLOOKUP(B2794,'2025-Q1'!$A$402:$A$448,'2025-Q1'!$A$402:$A$448,"avail") -> avail | F2794: =_xlfn.XLOOKUP(B2794,'[2]!! -- Stock Universe 12.11.24'!$C$2:$C$1621,'[2]!! -- Stock Universe 12.11.24'!$E$2:$E$1621,"")
A2795: 45714.597 | B2795: AIN | C2795: on 2/26/25, 4:20 PM After Market Eastern Standard Time | D2795: =_xlfn.XLOOKUP(B2795,Indices!$A$2:$A$2676,Indices!$B$2:$B$2676,"") -> IWM | E2795: =_xlfn.XLOOKUP(B2795,'2025-Q1'!$A$402:$A$448,'2025-Q1'!$A$402:$A$448,"avail") -> avail | F2795: =_xlfn.XLOOKUP(B2795,'[2]!! -- Stock Universe 12.11.24'!$C$2:$C$1621,'[2]!! -- Stock Universe 12.11.24'!$E$2:$E$1621,"")
A2796: 45714.597 | B2796: HG | C2796: on 2/26/25, 4:20 PM After Market Eastern Standard Time | D2796: =_xlfn.XLOOKUP(B2796,Indices!$A$2:$A$2676,Indices!$B$2:$B$2676,"") -> IWM | E2796: =_xlfn.XLOOKUP(B2796,'2025-Q1'!$A$402:$A$448,'2025-Q1'!$A$402:$A$448,"avail") -> avail | F2796: =_xlfn.XLOOKUP(B2796,'[2]!! -- Stock Universe 12.11.24'!$C$2:$C$1621,'[2]!! -- Stock Universe 12.11.24'!$E$2:$E$1621,"")
A2797: 45714.599 | B2797: APA | C2797: on 2/26/25, 4:22 PM After Market Eastern Standard Time | D2797: =_xlfn.XLOOKUP(B2797,Indices!$A$2:$A$2676,Indices!$B$2:$B$2676,"") -> SP500 | E2797: =_xlfn.XLOOKUP(B2797,'2025-Q1'!$A$402:$A$448,'2025-Q1'!$A$402:$A$448,"avail") -> avail | F2797: =_xlfn.XLOOKUP(B2797,'[2]!! -- Stock Universe 12.11.24'!$C$2:$C$1621,'[2]!! -- Stock Universe 12.11.24'!$E$2:$E$1621,"") -> Energy
A2798: 45714.599 | B2798: CRGY | C2798: on 2/26/25, 4:23 PM After Market Eastern Standard Time | D2798: =_xlfn.XLOOKUP(B2798,Indices!$A$2:$A$2676,Indices!$B$2:$B$2676,"") -> IWM | E2798: =_xlfn.XLOOKUP(B2798,'2025-Q1'!$A$402:$A$448,'2025-Q1'!$A$402:$A$448,"avail") -> avail | F2798: =_xlfn.XLOOKUP(B2798,'[2]!! -- Stock Universe 12.11.24'!$C$2:$C$1621,'[2]!! -- Stock Universe 12.11.24'!$E$2:$E$1621,"") -> Energy
A2799: 45714.601 | B2799: LSF | C2799: on 2/26/25, 4:25 PM After Market Eastern Standard Time | D2799: =_xlfn.XLOOKUP(B2799,Indices!$A$2:$A$2676,Indices!$B$2:$B$2676,"") | E2799: =_xlfn.XLOOKUP(B2799,'2025-Q1'!$A$402:$A$448,'2025-Q1'!$A$402:$A$448,"avail") -> avail | F2799: =_xlfn.XLOOKUP(B2799,'[2]!! -- Stock Universe 12.11.24'!$C$2:$C$1621,'[2]!! -- Stock Universe 12.11.24'!$E$2:$E$1621,"")
A2800: 45714.601 | B2800: ARIS | C2800: on 2/26/25, 4:26 PM After Market Eastern Standard Time | D2800: =_xlfn.XLOOKUP(B2800,Indices!$A$2:$A$2676,Indices!$B$2:$B$2676,"") -> IWM | E2800: =_xlfn.XLOOKUP(B2800,'2025-Q1'!$A$402:$A$448,'2025-Q1'!$A$402:$A$448,"avail") -> avail | F2800: =_xlfn.XLOOKUP(B2800,'[2]!! -- Stock Universe 12.11.24'!$C$2:$C$1621,'[2]!! -- Stock Universe 12.11.24'!$E$2:$E$1621,"")
A2801: 45714.604 | B2801: AMED | C2801: on 2/26/25, 4:30 PM After Market Eastern Standard Time | D2801: =_xlfn.XLOOKUP(B2801,Indices!$A$2:$A$2676,Indices!$B$2:$B$2676,"") -> S&P Mid | E2801: =_xlfn.XLOOKUP(B2801,'2025-Q1'!$A$402:$A$448,'2025-Q1'!$A$402:$A$448,"avail") -> avail | F2801: =_xlfn.XLOOKUP(B2801,'[2]!! -- Stock Universe 12.11.24'!$C$2:$C$1621,'[2]!! -- Stock Universe 12.11.24'!$E$2:$E$1621,"")
A2802: 45714.604 | B2802: MEG | C2802: on 2/26/25, 4:30 PM After Market Eastern Standard Time | D2802: =_xlfn.XLOOKUP(B2802,Indices!$A$2:$A$2676,Indices!$B$2:$B$2676,"") -> IWM | E2802: =_xlfn.XLOOKUP(B2802,'2025-Q1'!$A$402:$A$448,'2025-Q1'!$A$402:$A$448,"avail") -> avail | F2802: =_xlfn.XLOOKUP(B2802,'[2]!! -- Stock Universe 12.11.24'!$C$2:$C$1621,'[2]!! -- Stock Universe 12.11.24'!$E$2:$E$1621,"") -> Industrials
A2803: 45714.604 | B2803: UMH | C2803: on 2/26/25, 4:30 PM After Market Eastern Standard Time | D2803: =_xlfn.XLOOKUP(B2803,Indices!$A$2:$A$2676,Indices!$B$2:$B$2676,"") -> IWM | E2803: =_xlfn.XLOOKUP(B2803,'2025-Q1'!$A$402:$A$448,'2025-Q1'!$A$402:$A$448,"avail") -> avail | F2803: =_xlfn.XLOOKUP(B2803,'[2]!! -- Stock Universe 12.11.24'!$C$2:$C$1621,'[2]!! -- Stock Universe 12.11.24'!$E$2:$E$1621,"")
...

Sheet Charts

Sheet SPDR Chart
D1: XLP | E1: XLI | F1: XLF | G1: XLV | H1: XLE | I1: XLRE | J1: XLY | K1: XLC | L1: XLK | M1: XLB | N1: XLU | O1: SMH | P1: INS | Q1: IGV
C2: 45667 | D2: =COUNTIFS('2025-Q1'!$E$4:$E$448,'SPDR Chart'!D$1,'2025-Q1'!$F$4:$F$448,'SPDR Chart'!$C2) -> 2 | E2: =COUNTIFS('2025-Q1'!$E$4:$E$448,'SPDR Chart'!E$1,'2025-Q1'!$F$4:$F$448,'SPDR Chart'!$C2) -> 1 | F2: =COUNTIFS('2025-Q1'!$E$4:$E$448,'SPDR Chart'!F$1,'2025-Q1'!$F$4:$F$448,'SPDR Chart'!$C2) -> 0 | G2: =COUNTIFS('2025-Q1'!$E$4:$E$448,'SPDR Chart'!G$1,'2025-Q1'!$F$4:$F$448,'SPDR Chart'!$C2) -> 0 | H2: =COUNTIFS('2025-Q1'!$E$4:$E$448,'SPDR Chart'!H$1,'2025-Q1'!$F$4:$F$448,'SPDR Chart'!$C2) -> 0 | I2: =COUNTIFS('2025-Q1'!$E$4:$E$448,'SPDR Chart'!I$1,'2025-Q1'!$F$4:$F$448,'SPDR Chart'!$C2) -> 0 | J2: =COUNTIFS('2025-Q1'!$E$4:$E$448,'SPDR Chart'!J$1,'2025-Q1'!$F$4:$F$448,'SPDR Chart'!$C2) -> 0 | K2: =COUNTIFS('2025-Q1'!$E$4:$E$448,'SPDR Chart'!K$1,'2025-Q1'!$F$4:$F$448,'SPDR Chart'!$C2) -> 0 | ... Q2: =COUNTIFS('2025-Q1'!$E$4:$E$448,'SPDR Chart'!Q$1,'2025-Q1'!$F$4:$F$448,'SPDR Chart'!$C2) -> 0
C3: 45672 | D3: =COUNTIFS('2025-Q1'!$E$4:$E$448,'SPDR Chart'!D$1,'2025-Q1'!$F$4:$F$448,'SPDR Chart'!$C3) -> 0 | E3: =COUNTIFS('2025-Q1'!$E$4:$E$448,'SPDR Chart'!E$1,'2025-Q1'!$F$4:$F$448,'SPDR Chart'!$C3) -> 0 | F3: =COUNTIFS('2025-Q1'!$E$4:$E$448,'SPDR Chart'!F$1,'2025-Q1'!$F$4:$F$448,'SPDR Chart'!$C3) -> 6 | G3: =COUNTIFS('2025-Q1'!$E$4:$E$448,'SPDR Chart'!G$1,'2025-Q1'!$F$4:$F$448,'SPDR Chart'!$C3) -> 0 | H3: =COUNTIFS('2025-Q1'!$E$4:$E$448,'SPDR Chart'!H$1,'2025-Q1'!$F$4:$F$448,'SPDR Chart'!$C3) -> 0 | I3: =COUNTIFS('2025-Q1'!$E$4:$E$448,'SPDR Chart'!I$1,'2025-Q1'!$F$4:$F$448,'SPDR Chart'!$C3) -> 0 | J3: =COUNTIFS('2025-Q1'!$E$4:$E$448,'SPDR Chart'!J$1,'2025-Q1'!$F$4:$F$448,'SPDR Chart'!$C3) -> 0 | K3: =COUNTIFS('2025-Q1'!$E$4:$E$448,'SPDR Chart'!K$1,'2025-Q1'!$F$4:$F$448,'SPDR Chart'!$C3) -> 0 | ... Q3: =COUNTIFS('2025-Q1'!$E$4:$E$448,'SPDR Chart'!Q$1,'2025-Q1'!$F$4:$F$448,'SPDR Chart'!$C3) -> 0
C4: 45673 | D4: =COUNTIFS('2025-Q1'!$E$4:$E$448,'SPDR Chart'!D$1,'2025-Q1'!$F$4:$F$448,'SPDR Chart'!$C4) -> 0 | E4: =COUNTIFS('2025-Q1'!$E$4:$E$448,'SPDR Chart'!E$1,'2025-Q1'!$F$4:$F$448,'SPDR Chart'!$C4) -> 1 | F4: =COUNTIFS('2025-Q1'!$E$4:$E$448,'SPDR Chart'!F$1,'2025-Q1'!$F$4:$F$448,'SPDR Chart'!$C4) -> 5 | G4: =COUNTIFS('2025-Q1'!$E$4:$E$448,'SPDR Chart'!G$1,'2025-Q1'!$F$4:$F$448,'SPDR Chart'!$C4) -> 0 | H4: =COUNTIFS('2025-Q1'!$E$4:$E$448,'SPDR Chart'!H$1,'2025-Q1'!$F$4:$F$448,'SPDR Chart'!$C4) -> 0 | I4: =COUNTIFS('2025-Q1'!$E$4:$E$448,'SPDR Chart'!I$1,'2025-Q1'!$F$4:$F$448,'SPDR Chart'!$C4) -> 0 | J4: =COUNTIFS('2025-Q1'!$E$4:$E$448,'SPDR Chart'!J$1,'2025-Q1'!$F$4:$F$448,'SPDR Chart'!$C4) -> 0 | K4: =COUNTIFS('2025-Q1'!$E$4:$E$448,'SPDR Chart'!K$1,'2025-Q1'!$F$4:$F$448,'SPDR Chart'!$C4) -> 0 | ... Q4: =COUNTIFS('2025-Q1'!$E$4:$E$448,'SPDR Chart'!Q$1,'2025-Q1'!$F$4:$F$448,'SPDR Chart'!$C4) -> 0
C5: 45674 | D5: =COUNTIFS('2025-Q1'!$E$4:$E$448,'SPDR Chart'!D$1,'2025-Q1'!$F$4:$F$448,'SPDR Chart'!$C5) -> 0 | E5: =COUNTIFS('2025-Q1'!$E$4:$E$448,'SPDR Chart'!E$1,'2025-Q1'!$F$4:$F$448,'SPDR Chart'!$C5) -> 1 | F5: =COUNTIFS('2025-Q1'!$E$4:$E$448,'SPDR Chart'!F$1,'2025-Q1'!$F$4:$F$448,'SPDR Chart'!$C5) -> 5 | G5: =COUNTIFS('2025-Q1'!$E$4:$E$448,'SPDR Chart'!G$1,'2025-Q1'!$F$4:$F$448,'SPDR Chart'!$C5) -> 0 | H5: =COUNTIFS('2025-Q1'!$E$4:$E$448,'SPDR Chart'!H$1,'2025-Q1'!$F$4:$F$448,'SPDR Chart'!$C5) -> 1 | I5: =COUNTIFS('2025-Q1'!$E$4:$E$448,'SPDR Chart'!I$1,'2025-Q1'!$F$4:$F$448,'SPDR Chart'!$C5) -> 0 | J5: =COUNTIFS('2025-Q1'!$E$4:$E$448,'SPDR Chart'!J$1,'2025-Q1'!$F$4:$F$448,'SPDR Chart'!$C5) -> 0 | K5: =COUNTIFS('2025-Q1'!$E$4:$E$448,'SPDR Chart'!K$1,'2025-Q1'!$F$4:$F$448,'SPDR Chart'!$C5) -> 0 | ... Q5: =COUNTIFS('2025-Q1'!$E$4:$E$448,'SPDR Chart'!Q$1,'2025-Q1'!$F$4:$F$448,'SPDR Chart'!$C5) -> 0
C6: 45678 | D6: =COUNTIFS('2025-Q1'!$E$4:$E$448,'SPDR Chart'!D$1,'2025-Q1'!$F$4:$F$448,'SPDR Chart'!$C6) -> 0 | E6: =COUNTIFS('2025-Q1'!$E$4:$E$448,'SPDR Chart'!E$1,'2025-Q1'!$F$4:$F$448,'SPDR Chart'!$C6) -> 2 | F6: =COUNTIFS('2025-Q1'!$E$4:$E$448,'SPDR Chart'!F$1,'2025-Q1'!$F$4:$F$448,'SPDR Chart'!$C6) -> 4 | G6: =COUNTIFS('2025-Q1'!$E$4:$E$448,'SPDR Chart'!G$1,'2025-Q1'!$F$4:$F$448,'SPDR Chart'!$C6) -> 0 | H6: =COUNTIFS('2025-Q1'!$E$4:$E$448,'SPDR Chart'!H$1,'2025-Q1'!$F$4:$F$448,'SPDR Chart'!$C6) -> 0 | I6: =COUNTIFS('2025-Q1'!$E$4:$E$448,'SPDR Chart'!I$1,'2025-Q1'!$F$4:$F$448,'SPDR Chart'!$C6) -> 0 | J6: =COUNTIFS('2025-Q1'!$E$4:$E$448,'SPDR Chart'!J$1,'2025-Q1'!$F$4:$F$448,'SPDR Chart'!$C6) -> 0 | K6: =COUNTIFS('2025-Q1'!$E$4:$E$448,'SPDR Chart'!K$1,'2025-Q1'!$F$4:$F$448,'SPDR Chart'!$C6) -> 1 | ... Q6: =COUNTIFS('2025-Q1'!$E$4:$E$448,'SPDR Chart'!Q$1,'2025-Q1'!$F$4:$F$448,'SPDR Chart'!$C6) -> 0
C7: 45679 | D7: =COUNTIFS('2025-Q1'!$E$4:$E$448,'SPDR Chart'!D$1,'2025-Q1'!$F$4:$F$448,'SPDR Chart'!$C7) -> 1 | E7: =COUNTIFS('2025-Q1'!$E$4:$E$448,'SPDR Chart'!E$1,'2025-Q1'!$F$4:$F$448,'SPDR Chart'!$C7) -> 2 | F7: =COUNTIFS('2025-Q1'!$E$4:$E$448,'SPDR Chart'!F$1,'2025-Q1'!$F$4:$F$448,'SPDR Chart'!$C7) -> 1 | G7: =COUNTIFS('2025-Q1'!$E$4:$E$448,'SPDR Chart'!G$1,'2025-Q1'!$F$4:$F$448,'SPDR Chart'!$C7) -> 2 | H7: =COUNTIFS('2025-Q1'!$E$4:$E$448,'SPDR Chart'!H$1,'2025-Q1'!$F$4:$F$448,'SPDR Chart'!$C7) -> 2 | I7: =COUNTIFS('2025-Q1'!$E$4:$E$448,'SPDR Chart'!I$1,'2025-Q1'!$F$4:$F$448,'SPDR Chart'!$C7) -> 0 | J7: =COUNTIFS('2025-Q1'!$E$4:$E$448,'SPDR Chart'!J$1,'2025-Q1'!$F$4:$F$448,'SPDR Chart'!$C7) -> 0 | K7: =COUNTIFS('2025-Q1'!$E$4:$E$448,'SPDR Chart'!K$1,'2025-Q1'!$F$4:$F$448,'SPDR Chart'!$C7) -> 0 | ... Q7: =COUNTIFS('2025-Q1'!$E$4:$E$448,'SPDR Chart'!Q$1,'2025-Q1'!$F$4:$F$448,'SPDR Chart'!$C7) -> 0
C8: 45680 | D8: =COUNTIFS('2025-Q1'!$E$4:$E$448,'SPDR Chart'!D$1,'2025-Q1'!$F$4:$F$448,'SPDR Chart'!$C8) -> 1 | E8: =COUNTIFS('2025-Q1'!$E$4:$E$448,'SPDR Chart'!E$1,'2025-Q1'!$F$4:$F$448,'SPDR Chart'!$C8) -> 3 | F8: =COUNTIFS('2025-Q1'!$E$4:$E$448,'SPDR Chart'!F$1,'2025-Q1'!$F$4:$F$448,'SPDR Chart'!$C8) -> 1 | G8: =COUNTIFS('2025-Q1'!$E$4:$E$448,'SPDR Chart'!G$1,'2025-Q1'!$F$4:$F$448,'SPDR Chart'!$C8) -> 1 | H8: =COUNTIFS('2025-Q1'!$E$4:$E$448,'SPDR Chart'!H$1,'2025-Q1'!$F$4:$F$448,'SPDR Chart'!$C8) -> 0 | I8: =COUNTIFS('2025-Q1'!$E$4:$E$448,'SPDR Chart'!I$1,'2025-Q1'!$F$4:$F$448,'SPDR Chart'!$C8) -> 0 | J8: =COUNTIFS('2025-Q1'!$E$4:$E$448,'SPDR Chart'!J$1,'2025-Q1'!$F$4:$F$448,'SPDR Chart'!$C8) -> 0 | K8: =COUNTIFS('2025-Q1'!$E$4:$E$448,'SPDR Chart'!K$1,'2025-Q1'!$F$4:$F$448,'SPDR Chart'!$C8) -> 0 | ... Q8: =COUNTIFS('2025-Q1'!$E$4:$E$448,'SPDR Chart'!Q$1,'2025-Q1'!$F$4:$F$448,'SPDR Chart'!$C8) -> 0
C9: 45681 | D9: =COUNTIFS('2025-Q1'!$E$4:$E$448,'SPDR Chart'!D$1,'2025-Q1'!$F$4:$F$448,'SPDR Chart'!$C9) -> 0 | E9: =COUNTIFS('2025-Q1'!$E$4:$E$448,'SPDR Chart'!E$1,'2025-Q1'!$F$4:$F$448,'SPDR Chart'!$C9) -> 0 | F9: =COUNTIFS('2025-Q1'!$E$4:$E$448,'SPDR Chart'!F$1,'2025-Q1'!$F$4:$F$448,'SPDR Chart'!$C9) -> 1 | G9: =COUNTIFS('2025-Q1'!$E$4:$E$448,'SPDR Chart'!G$1,'2025-Q1'!$F$4:$F$448,'SPDR Chart'!$C9) -> 1 | H9: =COUNTIFS('2025-Q1'!$E$4:$E$448,'SPDR Chart'!H$1,'2025-Q1'!$F$4:$F$448,'SPDR Chart'!$C9) -> 0 | I9: =COUNTIFS('2025-Q1'!$E$4:$E$448,'SPDR Chart'!I$1,'2025-Q1'!$F$4:$F$448,'SPDR Chart'!$C9) -> 0 | J9: =COUNTIFS('2025-Q1'!$E$4:$E$448,'SPDR Chart'!J$1,'2025-Q1'!$F$4:$F$448,'SPDR Chart'!$C9) -> 0 | K9: =COUNTIFS('2025-Q1'!$E$4:$E$448,'SPDR Chart'!K$1,'2025-Q1'!$F$4:$F$448,'SPDR Chart'!$C9) -> 1 | ... Q9: =COUNTIFS('2025-Q1'!$E$4:$E$448,'SPDR Chart'!Q$1,'2025-Q1'!$F$4:$F$448,'SPDR Chart'!$C9) -> 0
C10: 45684 | D10: =COUNTIFS('2025-Q1'!$E$4:$E$448,'SPDR Chart'!D$1,'2025-Q1'!$F$4:$F$448,'SPDR Chart'!$C10) -> 0 | E10: =COUNTIFS('2025-Q1'!$E$4:$E$448,'SPDR Chart'!E$1,'2025-Q1'!$F$4:$F$448,'SPDR Chart'!$C10) -> 0 | F10: =COUNTIFS('2025-Q1'!$E$4:$E$448,'SPDR Chart'!F$1,'2025-Q1'!$F$4:$F$448,'SPDR Chart'!$C10) -> 0 | G10: =COUNTIFS('2025-Q1'!$E$4:$E$448,'SPDR Chart'!G$1,'2025-Q1'!$F$4:$F$448,'SPDR Chart'!$C10) -> 0 | H10: =COUNTIFS('2025-Q1'!$E$4:$E$448,'SPDR Chart'!H$1,'2025-Q1'!$F$4:$F$448,'SPDR Chart'!$C10) -> 0 | I10: =COUNTIFS('2025-Q1'!$E$4:$E$448,'SPDR Chart'!I$1,'2025-Q1'!$F$4:$F$448,'SPDR Chart'!$C10) -> 0 | J10: =COUNTIFS('2025-Q1'!$E$4:$E$448,'SPDR Chart'!J$1,'2025-Q1'!$F$4:$F$448,'SPDR Chart'!$C10) -> 0 | K10: =COUNTIFS('2025-Q1'!$E$4:$E$448,'SPDR Chart'!K$1,'2025-Q1'!$F$4:$F$448,'SPDR Chart'!$C10) -> 1 | ... Q10: =COUNTIFS('2025-Q1'!$E$4:$E$448,'SPDR Chart'!Q$1,'2025-Q1'!$F$4:$F$448,'SPDR Chart'!$C10) -> 0
C11: 45685 | D11: =COUNTIFS('2025-Q1'!$E$4:$E$448,'SPDR Chart'!D$1,'2025-Q1'!$F$4:$F$448,'SPDR Chart'!$C11) -> 2 | E11: =COUNTIFS('2025-Q1'!$E$4:$E$448,'SPDR Chart'!E$1,'2025-Q1'!$F$4:$F$448,'SPDR Chart'!$C11) -> 4 | F11: =COUNTIFS('2025-Q1'!$E$4:$E$448,'SPDR Chart'!F$1,'2025-Q1'!$F$4:$F$448,'SPDR Chart'!$C11) -> 2 | G11: =COUNTIFS('2025-Q1'!$E$4:$E$448,'SPDR Chart'!G$1,'2025-Q1'!$F$4:$F$448,'SPDR Chart'!$C11) -> 1 | H11: =COUNTIFS('2025-Q1'!$E$4:$E$448,'SPDR Chart'!H$1,'2025-Q1'!$F$4:$F$448,'SPDR Chart'!$C11) -> 0 | I11: =COUNTIFS('2025-Q1'!$E$4:$E$448,'SPDR Chart'!I$1,'2025-Q1'!$F$4:$F$448,'SPDR Chart'!$C11) -> 0 | J11: =COUNTIFS('2025-Q1'!$E$4:$E$448,'SPDR Chart'!J$1,'2025-Q1'!$F$4:$F$448,'SPDR Chart'!$C11) -> 3 | K11: =COUNTIFS('2025-Q1'!$E$4:$E$448,'SPDR Chart'!K$1,'2025-Q1'!$F$4:$F$448,'SPDR Chart'!$C11) -> 0 | ... Q11: =COUNTIFS('2025-Q1'!$E$4:$E$448,'SPDR Chart'!Q$1,'2025-Q1'!$F$4:$F$448,'SPDR Chart'!$C11) -> 0
C12: 45686 | D12: =COUNTIFS('2025-Q1'!$E$4:$E$448,'SPDR Chart'!D$1,'2025-Q1'!$F$4:$F$448,'SPDR Chart'!$C12) -> 0 | E12: =COUNTIFS('2025-Q1'!$E$4:$E$448,'SPDR Chart'!E$1,'2025-Q1'!$F$4:$F$448,'SPDR Chart'!$C12) -> 7 | F12: =COUNTIFS('2025-Q1'!$E$4:$E$448,'SPDR Chart'!F$1,'2025-Q1'!$F$4:$F$448,'SPDR Chart'!$C12) -> 3 | G12: =COUNTIFS('2025-Q1'!$E$4:$E$448,'SPDR Chart'!G$1,'2025-Q1'!$F$4:$F$448,'SPDR Chart'!$C12) -> 1 | H12: =COUNTIFS('2025-Q1'!$E$4:$E$448,'SPDR Chart'!H$1,'2025-Q1'!$F$4:$F$448,'SPDR Chart'!$C12) -> 0 | I12: =COUNTIFS('2025-Q1'!$E$4:$E$448,'SPDR Chart'!I$1,'2025-Q1'!$F$4:$F$448,'SPDR Chart'!$C12) -> 0 | J12: =COUNTIFS('2025-Q1'!$E$4:$E$448,'SPDR Chart'!J$1,'2025-Q1'!$F$4:$F$448,'SPDR Chart'!$C12) -> 2 | K12: =COUNTIFS('2025-Q1'!$E$4:$E$448,'SPDR Chart'!K$1,'2025-Q1'!$F$4:$F$448,'SPDR Chart'!$C12) -> 2 | ... Q12: =COUNTIFS('2025-Q1'!$E$4:$E$448,'SPDR Chart'!Q$1,'2025-Q1'!$F$4:$F$448,'SPDR Chart'!$C12) -> 1
C13: 45687 | D13: =COUNTIFS('2025-Q1'!$E$4:$E$448,'SPDR Chart'!D$1,'2025-Q1'!$F$4:$F$448,'SPDR Chart'!$C13) -> 1 | E13: =COUNTIFS('2025-Q1'!$E$4:$E$448,'SPDR Chart'!E$1,'2025-Q1'!$F$4:$F$448,'SPDR Chart'!$C13) -> 8 | F13: =COUNTIFS('2025-Q1'!$E$4:$E$448,'SPDR Chart'!F$1,'2025-Q1'!$F$4:$F$448,'SPDR Chart'!$C13) -> 3 | G13: =COUNTIFS('2025-Q1'!$E$4:$E$448,'SPDR Chart'!G$1,'2025-Q1'!$F$4:$F$448,'SPDR Chart'!$C13) -> 4 | H13: =COUNTIFS('2025-Q1'!$E$4:$E$448,'SPDR Chart'!H$1,'2025-Q1'!$F$4:$F$448,'SPDR Chart'!$C13) -> 2 | I13: =COUNTIFS('2025-Q1'!$E$4:$E$448,'SPDR Chart'!I$1,'2025-Q1'!$F$4:$F$448,'SPDR Chart'!$C13) -> 0 | J13: =COUNTIFS('2025-Q1'!$E$4:$E$448,'SPDR Chart'!J$1,'2025-Q1'!$F$4:$F$448,'SPDR Chart'!$C13) -> 2 | K13: =COUNTIFS('2025-Q1'!$E$4:$E$448,'SPDR Chart'!K$1,'2025-Q1'!$F$4:$F$448,'SPDR Chart'!$C13) -> 1 | ... Q13: =COUNTIFS('2025-Q1'!$E$4:$E$448,'SPDR Chart'!Q$1,'2025-Q1'!$F$4:$F$448,'SPDR Chart'!$C13) -> 5
... C47: 45757 | D47: =COUNTIFS('2025-Q1'!$E$4:$E$448,'SPDR Chart'!D$1,'2025-Q1'!$F$4:$F$448,'SPDR Chart'!$C47) -> 0 | E47: =COUNTIFS('2025-Q1'!$E$4:$E$448,'SPDR Chart'!E$1,'2025-Q1'!$F$4:$F$448,'SPDR Chart'!$C47) -> 0 | F47: =COUNTIFS('2025-Q1'!$E$4:$E$448,'SPDR Chart'!F$1,'2025-Q1'!$F$4:$F$448,'SPDR Chart'!$C47) -> 0 | G47: =COUNTIFS('2025-Q1'!$E$4:$E$448,'SPDR Chart'!G$1,'2025-Q1'!$F$4:$F$448,'SPDR Chart'!$C47) -> 0 | H47: =COUNTIFS('2025-Q1'!$E$4:$E$448,'SPDR Chart'!H$1,'2025-Q1'!$F$4:$F$448,'SPDR Chart'!$C47) -> 0 | I47: =COUNTIFS('2025-Q1'!$E$4:$E$448,'SPDR Chart'!I$1,'2025-Q1'!$F$4:$F$448,'SPDR Chart'!$C47) -> 0 | J47: =COUNTIFS('2025-Q1'!$E$4:$E$448,'SPDR Chart'!J$1,'2025-Q1'!$F$4:$F$448,'SPDR Chart'!$C47) -> 0 | K47: =COUNTIFS('2025-Q1'!$E$4:$E$448,'SPDR Chart'!K$1,'2025-Q1'!$F$4:$F$448,'SPDR Chart'!$C47) -> 0 | ... Q47: =COUNTIFS('2025-Q1'!$E$4:$E$448,'SPDR Chart'!Q$1,'2025-Q1'!$F$4:$F$448,'SPDR Chart'!$C47) -> 0

Sheet Rev Curves
AB43: .
A441: Up Trends
A442: Sector | B442: # | C442: % Gap Up | D442: Expectancy
A443: XLK | B443: =_xlfn.XLOOKUP('Rev Curves'!$A443,'Stats Roll Up'!$B$4:$B$20,'Stats Roll Up'!$F$4:$F$20) -> 10 | C443: =_xlfn.XLOOKUP('Rev Curves'!$A443,'Stats Roll Up'!$B$4:$B$20,'Stats Roll Up'!$G$4:$G$20) -> 0.7 | D443: =_xlfn.XLOOKUP(A443,Expectancy!$P$3:$P$19,Expectancy!$Q$3:$Q$19) -> 0.35290545
A444: XLC | B444: =_xlfn.XLOOKUP('Rev Curves'!A444,'Stats Roll Up'!$B$4:$B$20,'Stats Roll Up'!$F$4:$F$20) -> 6 | C444: =_xlfn.XLOOKUP('Rev Curves'!$A444,'Stats Roll Up'!$B$4:$B$20,'Stats Roll Up'!$G$4:$G$20) -> 0.83333333 | D444: =_xlfn.XLOOKUP(A444,Expectancy!$P$3:$P$19,Expectancy!$Q$3:$Q$19) -> 0.43526477
A445: IGV | B445: =_xlfn.XLOOKUP('Rev Curves'!A445,'Stats Roll Up'!$B$4:$B$20,'Stats Roll Up'!$F$4:$F$20) -> 10 | C445: =_xlfn.XLOOKUP('Rev Curves'!$A445,'Stats Roll Up'!$B$4:$B$20,'Stats Roll Up'!$G$4:$G$20) -> 0.7 | D445: =_xlfn.XLOOKUP(A445,Expectancy!$P$3:$P$19,Expectancy!$Q$3:$Q$19) -> 1.0051962
A446: SMH | B446: =_xlfn.XLOOKUP('Rev Curves'!A446,'Stats Roll Up'!$B$4:$B$20,'Stats Roll Up'!$F$4:$F$20) -> 0 | C446: =_xlfn.XLOOKUP('Rev Curves'!$A446,'Stats Roll Up'!$B$4:$B$20,'Stats Roll Up'!$G$4:$G$20) -> 0 | D446: =_xlfn.XLOOKUP(A446,Expectancy!$P$3:$P$19,Expectancy!$Q$3:$Q$19) -> 0
A447: XLI | B447: =_xlfn.XLOOKUP('Rev Curves'!A447,'Stats Roll Up'!$B$4:$B$20,'Stats Roll Up'!$F$4:$F$20) -> 15 | C447: =_xlfn.XLOOKUP('Rev Curves'!$A447,'Stats Roll Up'!$B$4:$B$20,'Stats Roll Up'!$G$4:$G$20) -> 0.6 | D447: =_xlfn.XLOOKUP(A447,Expectancy!$P$3:$P$19,Expectancy!$Q$3:$Q$19) -> -0.041762477
A448: XLY | B448: =_xlfn.XLOOKUP('Rev Curves'!A448,'Stats Roll Up'!$B$4:$B$20,'Stats Roll Up'!$F$4:$F$20) -> 9 | C448: =_xlfn.XLOOKUP('Rev Curves'!$A448,'Stats Roll Up'!$B$4:$B$20,'Stats Roll Up'!$G$4:$G$20) -> 0.33333333 | D448: =_xlfn.XLOOKUP(A448,Expectancy!$P$3:$P$19,Expectancy!$Q$3:$Q$19) -> 0.094642214
A449: XLP | B449: =_xlfn.XLOOKUP('Rev Curves'!A449,'Stats Roll Up'!$B$4:$B$20,'Stats Roll Up'!$F$4:$F$20) -> 4 | C449: =_xlfn.XLOOKUP('Rev Curves'!$A449,'Stats Roll Up'!$B$4:$B$20,'Stats Roll Up'!$G$4:$G$20) -> 0.5 | D449: =_xlfn.XLOOKUP(A449,Expectancy!$P$3:$P$19,Expectancy!$Q$3:$Q$19) -> 0.26476024
A450: XLF | B450: =_xlfn.XLOOKUP('Rev Curves'!A450,'Stats Roll Up'!$B$4:$B$20,'Stats Roll Up'!$F$4:$F$20) -> 28 | C450: =_xlfn.XLOOKUP('Rev Curves'!$A450,'Stats Roll Up'!$B$4:$B$20,'Stats Roll Up'!$G$4:$G$20) -> 0.5 | D450: =_xlfn.XLOOKUP(A450,Expectancy!$P$3:$P$19,Expectancy!$Q$3:$Q$19) -> -0.079483353
A451: XLV | B451: =_xlfn.XLOOKUP('Rev Curves'!A451,'Stats Roll Up'!$B$4:$B$20,'Stats Roll Up'!$F$4:$F$20) -> 13 | C451: =_xlfn.XLOOKUP('Rev Curves'!$A451,'Stats Roll Up'!$B$4:$B$20,'Stats Roll Up'!$G$4:$G$20) -> 0.23076923 | D451: =_xlfn.XLOOKUP(A451,Expectancy!$P$3:$P$19,Expectancy!$Q$3:$Q$19) -> -0.45514117
A452: XLB | B452: =_xlfn.XLOOKUP('Rev Curves'!A452,'Stats Roll Up'!$B$4:$B$20,'Stats Roll Up'!$F$4:$F$20) -> 2 | C452: =_xlfn.XLOOKUP('Rev Curves'!$A452,'Stats Roll Up'!$B$4:$B$20,'Stats Roll Up'!$G$4:$G$20) -> 0 | D452: =_xlfn.XLOOKUP(A452,Expectancy!$P$3:$P$19,Expectancy!$Q$3:$Q$19) -> -0.11318819
A453: ALL | B453: =_xlfn.XLOOKUP('Rev Curves'!A453,'Stats Roll Up'!$B$4:$B$20,'Stats Roll Up'!$F$4:$F$20) -> 101 | C453: =_xlfn.XLOOKUP('Rev Curves'!$A453,'Stats Roll Up'!$B$4:$B$20,'Stats Roll Up'!$G$4:$G$20) -> 0.52475248 | D453: =_xlfn.XLOOKUP(A453,Expectancy!$P$3:$P$19,Expectancy!$Q$3:$Q$19) -> 0.099102767
A469: Down Trends
A470: Sector | B470: # | C470: % Gap Dn | D470: Expectancy
A471: XLK | B471: =_xlfn.XLOOKUP('Rev Curves'!$A471,'Stats Roll Up'!$B$4:$B$20,'Stats Roll Up'!$J$4:$J$20) -> 7 | C471: =_xlfn.XLOOKUP('Rev Curves'!$A471,'Stats Roll Up'!$B$4:$B$20,'Stats Roll Up'!$Y$4:$Y$20) -> 0.57142857 | D471: =_xlfn.XLOOKUP(A471,Expectancy!$P$3:$P$19,Expectancy!$R$3:$R$19) -> 1.1895734
A472: XLC | B472: =_xlfn.XLOOKUP('Rev Curves'!A472,'Stats Roll Up'!$B$4:$B$20,'Stats Roll Up'!$J$4:$J$20) -> 5 | C472: =_xlfn.XLOOKUP('Rev Curves'!$A472,'Stats Roll Up'!$B$4:$B$20,'Stats Roll Up'!$Y$4:$Y$20) -> 0.4 | D472: =_xlfn.XLOOKUP(A472,Expectancy!$P$3:$P$19,Expectancy!$R$3:$R$19) -> -0.040038914
A473: IGV | B473: =_xlfn.XLOOKUP('Rev Curves'!A473,'Stats Roll Up'!$B$4:$B$20,'Stats Roll Up'!$J$4:$J$20) -> 11 | C473: =_xlfn.XLOOKUP('Rev Curves'!$A473,'Stats Roll Up'!$B$4:$B$20,'Stats Roll Up'!$Y$4:$Y$20) -> 0.72727273 | D473: =_xlfn.XLOOKUP(A473,Expectancy!$P$3:$P$19,Expectancy!$R$3:$R$19) -> 0.78642334
A474: SMH | B474: =_xlfn.XLOOKUP('Rev Curves'!A474,'Stats Roll Up'!$B$4:$B$20,'Stats Roll Up'!$J$4:$J$20) -> 6 | C474: =_xlfn.XLOOKUP('Rev Curves'!$A474,'Stats Roll Up'!$B$4:$B$20,'Stats Roll Up'!$Y$4:$Y$20) -> 0.66666667 | D474: =_xlfn.XLOOKUP(A474,Expectancy!$P$3:$P$19,Expectancy!$R$3:$R$19) -> 0.69153964
A475: XLI | B475: =_xlfn.XLOOKUP('Rev Curves'!A475,'Stats Roll Up'!$B$4:$B$20,'Stats Roll Up'!$J$4:$J$20) -> 15 | C475: =_xlfn.XLOOKUP('Rev Curves'!$A475,'Stats Roll Up'!$B$4:$B$20,'Stats Roll Up'!$Y$4:$Y$20) -> 0.66666667 | D475: =_xlfn.XLOOKUP(A475,Expectancy!$P$3:$P$19,Expectancy!$R$3:$R$19) -> 0.3117803
A476: XLY | B476: =_xlfn.XLOOKUP('Rev Curves'!A476,'Stats Roll Up'!$B$4:$B$20,'Stats Roll Up'!$J$4:$J$20) -> 17 | C476: =_xlfn.XLOOKUP('Rev Curves'!$A476,'Stats Roll Up'!$B$4:$B$20,'Stats Roll Up'!$Y$4:$Y$20) -> 0.47058824 | D476: =_xlfn.XLOOKUP(A476,Expectancy!$P$3:$P$19,Expectancy!$R$3:$R$19) -> -0.094786291
A477: XLP | B477: =_xlfn.XLOOKUP('Rev Curves'!A477,'Stats Roll Up'!$B$4:$B$20,'Stats Roll Up'!$J$4:$J$20) -> 20 | C477: =_xlfn.XLOOKUP('Rev Curves'!$A477,'Stats Roll Up'!$B$4:$B$20,'Stats Roll Up'!$Y$4:$Y$20) -> 0.7 | D477: =_xlfn.XLOOKUP(A477,Expectancy!$P$3:$P$19,Expectancy!$R$3:$R$19) -> 0.3076902
A478: XLF | B478: =_xlfn.XLOOKUP('Rev Curves'!A478,'Stats Roll Up'!$B$4:$B$20,'Stats Roll Up'!$J$4:$J$20) -> 3 | C478: =_xlfn.XLOOKUP('Rev Curves'!$A478,'Stats Roll Up'!$B$4:$B$20,'Stats Roll Up'!$Y$4:$Y$20) -> 0 | D478: =_xlfn.XLOOKUP(A478,Expectancy!$P$3:$P$19,Expectancy!$R$3:$R$19) -> -0.57605219
A479: XLV | B479: =_xlfn.XLOOKUP('Rev Curves'!A479,'Stats Roll Up'!$B$4:$B$20,'Stats Roll Up'!$J$4:$J$20) -> 13 | C479: =_xlfn.XLOOKUP('Rev Curves'!$A479,'Stats Roll Up'!$B$4:$B$20,'Stats Roll Up'!$Y$4:$Y$20) -> 0.61538462 | D479: =_xlfn.XLOOKUP(A479,Expectancy!$P$3:$P$19,Expectancy!$R$3:$R$19) -> 0.18997806
A480: XLB | B480: =_xlfn.XLOOKUP('Rev Curves'!A480,'Stats Roll Up'!$B$4:$B$20,'Stats Roll Up'!$J$4:$J$20) -> 14 | C480: =_xlfn.XLOOKUP('Rev Curves'!$A480,'Stats Roll Up'!$B$4:$B$20,'Stats Roll Up'!$Y$4:$Y$20) -> 0.64285714 | D480: =_xlfn.XLOOKUP(A480,Expectancy!$P$3:$P$19,Expectancy!$R$3:$R$19) -> 0.73529829
A481: ALL | B481: =_xlfn.XLOOKUP('Rev Curves'!A481,'Stats Roll Up'!$B$4:$B$20,'Stats Roll Up'!$J$4:$J$20) -> 128 | C481: =_xlfn.XLOOKUP('Rev Curves'!$A481,'Stats Roll Up'!$B$4:$B$20,'Stats Roll Up'!$Y$4:$Y$20) -> 0.59375 | D481: =_xlfn.XLOOKUP(A481,Expectancy!$P$3:$P$19,Expectancy!$R$3:$R$19) -> 0.33981949
A498: SW Trends
A499: Sector | B499: # | C499: % Gap Up | D499: Expectancy
A500: XLK | B500: =_xlfn.XLOOKUP('Rev Curves'!$A500,'Stats Roll Up'!$B$4:$B$20,'Stats Roll Up'!$N$4:$N$20) -> 16 | C500: =_xlfn.XLOOKUP('Rev Curves'!$A500,'Stats Roll Up'!$B$4:$B$20,'Stats Roll Up'!$O$4:$O$20) -> 0.5 | D500: =_xlfn.XLOOKUP(A500,Expectancy!$P$3:$P$19,Expectancy!$S$3:$S$19) -> -0.17081772
A501: XLC | B501: =_xlfn.XLOOKUP('Rev Curves'!A501,'Stats Roll Up'!$B$4:$B$20,'Stats Roll Up'!$N$4:$N$20) -> 6 | C501: =_xlfn.XLOOKUP('Rev Curves'!$A501,'Stats Roll Up'!$B$4:$B$20,'Stats Roll Up'!$O$4:$O$20) -> 0.66666667 | D501: =_xlfn.XLOOKUP(A501,Expectancy!$P$3:$P$19,Expectancy!$S$3:$S$19) -> 0.70195709
A502: IGV | B502: =_xlfn.XLOOKUP('Rev Curves'!A502,'Stats Roll Up'!$B$4:$B$20,'Stats Roll Up'!$N$4:$N$20) -> 23 | C502: =_xlfn.XLOOKUP('Rev Curves'!$A502,'Stats Roll Up'!$B$4:$B$20,'Stats Roll Up'!$O$4:$O$20) -> 0.47826087 | D502: =_xlfn.XLOOKUP(A502,Expectancy!$P$3:$P$19,Expectancy!$S$3:$S$19) -> 0.27741611
A503: SMH | B503: =_xlfn.XLOOKUP('Rev Curves'!A503,'Stats Roll Up'!$B$4:$B$20,'Stats Roll Up'!$N$4:$N$20) -> 14 | C503: =_xlfn.XLOOKUP('Rev Curves'!$A503,'Stats Roll Up'!$B$4:$B$20,'Stats Roll Up'!$O$4:$O$20) -> 0.57142857 | D503: =_xlfn.XLOOKUP(A503,Expectancy!$P$3:$P$19,Expectancy!$S$3:$S$19) -> -0.16876071
A504: XLI | B504: =_xlfn.XLOOKUP('Rev Curves'!A504,'Stats Roll Up'!$B$4:$B$20,'Stats Roll Up'!$N$4:$N$20) -> 38 | C504: =_xlfn.XLOOKUP('Rev Curves'!$A504,'Stats Roll Up'!$B$4:$B$20,'Stats Roll Up'!$O$4:$O$20) -> 0.47368421 | D504: =_xlfn.XLOOKUP(A504,Expectancy!$P$3:$P$19,Expectancy!$S$3:$S$19) -> 0.02407352
A505: XLY | B505: =_xlfn.XLOOKUP('Rev Curves'!A505,'Stats Roll Up'!$B$4:$B$20,'Stats Roll Up'!$N$4:$N$20) -> 23 | C505: =_xlfn.XLOOKUP('Rev Curves'!$A505,'Stats Roll Up'!$B$4:$B$20,'Stats Roll Up'!$O$4:$O$20) -> 0.73913043 | D505: =_xlfn.XLOOKUP(A505,Expectancy!$P$3:$P$19,Expectancy!$S$3:$S$19) -> 0.48685637
A506: XLP | B506: =_xlfn.XLOOKUP('Rev Curves'!A506,'Stats Roll Up'!$B$4:$B$20,'Stats Roll Up'!$N$4:$N$20) -> 11 | C506: =_xlfn.XLOOKUP('Rev Curves'!$A506,'Stats Roll Up'!$B$4:$B$20,'Stats Roll Up'!$O$4:$O$20) -> 0.54545455 | D506: =_xlfn.XLOOKUP(A506,Expectancy!$P$3:$P$19,Expectancy!$S$3:$S$19) -> 0.40561946
A507: XLF | B507: =_xlfn.XLOOKUP('Rev Curves'!A507,'Stats Roll Up'!$B$4:$B$20,'Stats Roll Up'!$N$4:$N$20) -> 18 | C507: =_xlfn.XLOOKUP('Rev Curves'!$A507,'Stats Roll Up'!$B$4:$B$20,'Stats Roll Up'!$O$4:$O$20) -> 0.61111111 | D507: =_xlfn.XLOOKUP(A507,Expectancy!$P$3:$P$19,Expectancy!$S$3:$S$19) -> 0.099793136
A508: XLV | B508: =_xlfn.XLOOKUP('Rev Curves'!A508,'Stats Roll Up'!$B$4:$B$20,'Stats Roll Up'!$N$4:$N$20) -> 29 | C508: =_xlfn.XLOOKUP('Rev Curves'!$A508,'Stats Roll Up'!$B$4:$B$20,'Stats Roll Up'!$O$4:$O$20) -> 0.44827586 | D508: =_xlfn.XLOOKUP(A508,Expectancy!$P$3:$P$19,Expectancy!$S$3:$S$19) -> -0.15084751
A509: XLB | B509: =_xlfn.XLOOKUP('Rev Curves'!A509,'Stats Roll Up'!$B$4:$B$20,'Stats Roll Up'!$N$4:$N$20) -> 10 | C509: =_xlfn.XLOOKUP('Rev Curves'!$A509,'Stats Roll Up'!$B$4:$B$20,'Stats Roll Up'!$O$4:$O$20) -> 0.3 | D509: =_xlfn.XLOOKUP(A509,Expectancy!$P$3:$P$19,Expectancy!$S$3:$S$19) -> -0.22212962
A510: ALL | B510: =_xlfn.XLOOKUP('Rev Curves'!A510,'Stats Roll Up'!$B$4:$B$20,'Stats Roll Up'!$N$4:$N$20) -> 215 | C510: =_xlfn.XLOOKUP('Rev Curves'!$A510,'Stats Roll Up'!$B$4:$B$20,'Stats Roll Up'!$O$4:$O$20) -> 0.51162791 | D510: =_xlfn.XLOOKUP(A510,Expectancy!$P$3:$P$19,Expectancy!$S$3:$S$19) -> 0.070355978

Sheet 2025-Q1
A1: Formulas --> | B1: {=IFERROR(_xlfn.XLOOKUP(A4,Earnings!$B$2:$B$9985,LEFT(Earnings!$C$2:$C$9985,37)),"Can't Find Date***")} -> on 1/10/25, 7:30 AM Before Market Eas | E1: =_xlfn.XLOOKUP(A1,[1]SP500!$A$2:$A$655,[1]SP500!$B$2:$B$655) -> #N/A | F1: =IFERROR(TRIM(MID(B1,FIND("/",B1,1)-2,8)),"") -> 1/10/25 | I1: ------------- Gap Data ------------- | N1: Hide These these columns track the strategies three pillars per trade and cumulatively | T1: Hide These these columns track the strategies three pillars per trade and cumulatively | Z1: Hide These (Sector 3 Pillars) these columns track the strategies three pillars per trade and cumulatively | AG1: Hide These (Sector 3 Pillars) these columns track the strategies three pillars per trade and cumulatively | AN1: Hide These (Sector 3 Pillars) these columns track the strategies three pillars per trade and cumulatively | AU1: Hide These (Sector 3 Pillars) these columns track the strategies three pillars per trade and cumulatively | BB1: Hide These (Sector 3 Pillars) these columns track the strategies three pillars per trade and cumulatively | BI1: Hide These (Sector 3 Pillars) these columns track the strategies three pillars per trade and cumulatively | BP1: Hide These (Sector 3 Pillars) these columns track the strategies three pillars per trade and cumulatively | BW1: Hide These (Sector 3 Pillars) these columns track the strategies three pillars per trade and cumulatively | CD1: Hide These (Sector 3 Pillars) these columns track the strategies three pillars per trade and cumulatively | CK1: Hide These (Sector 3 Pillars) these columns track the strategies three pillars per trade and cumulatively | CR1: Hide These (Sector 3 Pillars) these columns track the strategies three pillars per trade and cumulatively | CY1: Hide These (Sector 3 Pillars) these columns track the strategies three pillars per trade and cumulatively | DF1: Hide These (Sector 3 Pillars) these columns track the strategies three pillars per trade and cumulatively | DM1: Hide These (Sector 3 Pillars) these columns track the strategies three pillars per trade and cumulatively | DT1: Hide These (Sector 3 Pillars) these columns track the strategies three pillars per trade and cumulatively | EA1: Hide These (Sector 3 Pillars) these columns track the strategies three pillars per trade and cumulatively | EH1: Strategy P&L | FX1: Hide These | GL1: MOC P&L | HB1: Actual P&L | HJ1: Money | HN1: Key Stats | HQ1: Risk Units | HX1: Expectancy | HZ1: Number of Stocks
A2: Cheat -> | B2: hide | C2: hide | E2: form | F2: form | G2: form | H2: f | I2: entry | J2: entry | K2: form | L2: form | M2: form | N2: form | O2: form | P2: form | Q2: form | R2: form | S2: form | T2: form | U2: form | V2: form | W2: form | X2: form | Y2: form | Z2: XLK | AA2: form | AB2: form | AC2: form | AD2: form | AE2: form | AF2: form | AG2: IGV | AH2: form | AI2: form | AJ2: form | AK2: form | AL2: form | AM2: form | AN2: XLY | AO2: form | AP2: form | AQ2: form | AR2: form | AS2: form | AT2: form | AU2: XLP | AV2: form | AW2: form | AX2: form | AY2: form | AZ2: form | BA2: form | BB2: XLC | BC2: form | BD2: form | BE2: form | BF2: form | BG2: form | BH2: form | BI2: XLF | BJ2: form | BK2: form | BL2: form | BM2: form | BN2: form | BO2: form | BP2: XLI | BQ2: form | BR2: form | BS2: form | BT2: form | BU2: form | BV2: form | BW2: XLV | BX2: form | BY2: form | BZ2: form | CA2: form | CB2: form | CC2: form | CD2: XLB | CE2: form | CF2: form | CG2: form | CH2: form | CI2: form | CJ2: form | CK2: SMH | CL2: form | CM2: form | CN2: form | CO2: form | CP2: form | CQ2: form | CR2: XLE | CS2: form | CT2: form | CU2: form | CV2: form | CW2: form | CX2: form | CY2: XLU | CZ2: form | DA2: form | DB2: form | DC2: form | DD2: form | DE2: form | DF2: XLRE | DG2: form | DH2: form | DI2: form | DJ2: form | DK2: form | DL2: form | DM2: INS | DN2: form | DO2: form | DP2: form | DQ2: form | DR2: form | DS2: form | DT2: H-INS | DU2: form | DV2: form | DW2: form | DX2: form | DY2: form | DZ2: form | EA2: XHB | EB2: form | EC2: form | ED2: form | EE2: form | EF2: form | EG2: form | EH2: form | EI2: form | EJ2: form | EK2: form | EL2: SPY | EM2: SPY | EN2: SPY | EO2: SPY | EP2: SPY | EQ2: SPY | ER2: SPY | ES2: SPY | ET2: Not Spy | EU2: Not Spy | EV2: Not Spy | EW2: Not Spy | EX2: Not Spy | EY2: Not Spy | EZ2: Not Spy | FA2: Not Spy | FB2: Gap ↓ from Dwn Tr | FD2: Gap ↑ from Dwn Tr | FF2: Gap ↑ from Up Tr | FH2: Gap ↓ from Up Tr | FJ2: Gap ↑ from Sw Tr | FL2: Gap ↓ from Sw Tr | FN2: hide | FO2: hide | FP2: form | FQ2: form | FR2: form | FS2: hide | FT2: hide | FU2: form | FV2: form | FW2: entry | GE2: form | GF2: entry | GG2: F/E | GH2: form | GI2: entry | GJ2: entry | GK2: form | GL2: form | GM2: Hide | GN2: Hide | GO2: Hide | GP2: Hide | GQ2: Hide | GR2: Hide | GS2: Hide | GT2: Hide | GU2: Hide | GV2: Hide | GW2: Hide | GX2: Hide | GY2: Hide | GZ2: entry | HA2: form | HB2: entry | HC2: form | HD2: form | HE2: form | HF2: form | HG2: form | HJ2: AveW | HK2: AveL | HL2: Sharpe$ | HM2: P/L | HN2: wins | HO2: losers | HP2: BA% | HQ2: AveW | HR2: AveL | HS2: Sharpe$ | HT2: Units | HU2: Overrides | HV2: SPY | HW2: Not SPY | HX2: SPY | HY2: Not SPY | HZ2: SPY | IA2: Not SPY
A3: Stock | B3: Earnings Date | C3: TrCh | D3: In SPY? | E3: Sector | F3: Date | G3: AMO, BMO | H3: S/O | I3: Close [entry] | J3: Open | K3: Gap % | L3: Gap P/L | M3: P&L Var. from Slippage | N3: Playing Up Trends Long | O3: Cumulative Playing Up Trends Long | P3: Playing Down Trends Short | Q3: Cumulative Playing Dwn Trends Short | R3: Playing Sideways Trends Long | S3: Cumulative Playing SW Trends Long | T3: R, Playing Up Trends Long | U3: Cumulative Playing Up Trends Long | V3: R, Playing Down Trends Short | W3: Cumulative Playing Dwn Trends Short | X3: R, Playing Sideways Trends Long | Y3: Cumulative Playing SW Trends Long | Z3: Playing Up Trends Long | AA3: Cumulative Playing Up Trends Long | AB3: Playing Down Trends Short | AC3: Cumulative Playing Dwn Trends Short | AD3: Playing Sideways Trends Long | AE3: Cumulative Playing SW Trends Long | AF3: TOTAL of Three Pillars | AG3: Playing Up Trends Long | AH3: Cumulative Playing Up Trends Long | AI3: Playing Down Trends Short | AJ3: Cumulative Playing Dwn Trends Short | AK3: Playing Sideways Trends Long | AL3: Cumulative Playing SW Trends Long | AM3: TOTAL of Three Pillars | AN3: Playing Up Trends Long | AO3: Cumulative Playing Up Trends Long | AP3: Playing Down Trends Short | AQ3: Cumulative Playing Dwn Trends Short | AR3: Playing Sideways Trends Long | AS3: Cumulative Playing SW Trends Long | AT3: TOTAL of Three Pillars | AU3: Playing Up Trends Long | AV3: Cumulative Playing Up Trends Long | AW3: Playing Down Trends Short | AX3: Cumulative Playing Dwn Trends Short | AY3: Playing Sideways Trends Long | AZ3: Cumulative Playing SW Trends Long | BA3: TOTAL of Three Pillars | BB3: Playing Up Trends Long | BC3: Cumulative Playing Up Trends Long | BD3: Playing Down Trends Short | BE3: Cumulative Playing Dwn Trends Short | BF3: Playing Sideways Trends Long | BG3: Cumulative Playing SW Trends Long | BH3: TOTAL of Three Pillars | BI3: Playing Up Trends Long | BJ3: Cumulative Playing Up Trends Long | BK3: Playing Down Trends Short | BL3: Cumulative Playing Dwn Trends Short | BM3: Playing Sideways Trends Long | BN3: Cumulative Playing SW Trends Long | BO3: TOTAL of Three Pillars | BP3: Playing Up Trends Long | BQ3: Cumulative Playing Up Trends Long | BR3: Playing Down Trends Short | BS3: Cumulative Playing Dwn Trends Short | BT3: Playing Sideways Trends Long | BU3: Cumulative Playing SW Trends Long | BV3: TOTAL of Three Pillars | BW3: Playing Up Trends Long | BX3: Cumulative Playing Up Trends Long | BY3: Playing Down Trends Short | BZ3: Cumulative Playing Dwn Trends Short | CA3: Playing Sideways Trends Long | CB3: Cumulative Playing SW Trends Long | CC3: TOTAL of Three Pillars | CD3: Playing Up Trends Long | CE3: Cumulative Playing Up Trends Long | CF3: Playing Down Trends Short | CG3: Cumulative Playing Dwn Trends Short | CH3: Playing Sideways Trends Long | CI3: Cumulative Playing SW Trends Long | CJ3: TOTAL of Three Pillars | CK3: Playing Up Trends Long | CL3: Cumulative Playing Up Trends Long | CM3: Playing Down Trends Short | CN3: Cumulative Playing Dwn Trends Short | CO3: Playing Sideways Trends Long | CP3: Cumulative Playing SW Trends Long | CQ3: TOTAL of Three Pillars | CR3: Playing Up Trends Long | CS3: Cumulative Playing Up Trends Long | CT3: Playing Down Trends Short | CU3: Cumulative Playing Dwn Trends Short | CV3: Playing Sideways Trends Long | CW3: Cumulative Playing SW Trends Long | CX3: TOTAL of Three Pillars | CY3: Playing Up Trends Long | CZ3: Cumulative Playing Up Trends Long | DA3: Playing Down Trends Short | DB3: Cumulative Playing Dwn Trends Short | DC3: Playing Sideways Trends Long | DD3: Cumulative Playing SW Trends Long | DE3: TOTAL of Three Pillars | DF3: Playing Up Trends Long | DG3: Cumulative Playing Up Trends Long | DH3: Playing Down Trends Short | DI3: Cumulative Playing Dwn Trends Short | DJ3: Playing Sideways Trends Long | DK3: Cumulative Playing SW Trends Long | DL3: TOTAL of Three Pillars | DM3: Playing Up Trends Long | DN3: Cumulative Playing Up Trends Long | DO3: Playing Down Trends Short | DP3: Cumulative Playing Dwn Trends Short | DQ3: Playing Sideways Trends Long | DR3: Cumulative Playing SW Trends Long | DS3: TOTAL of Three Pillars | DT3: Playing Up Trends Long | DU3: Cumulative Playing Up Trends Long | DV3: Playing Down Trends Short | DW3: Cumulative Playing Dwn Trends Short | DX3: Playing Sideways Trends Long | DY3: Cumulative Playing SW Trends Long | DZ3: TOTAL of Three Pillars | EA3: Playing Up Trends Long | EB3: Cumulative Playing Up Trends Long | EC3: Playing Down Trends Short | ED3: Cumulative Playing Dwn Trends Short | EE3: Playing Sideways Trends Long | EF3: Cumulative Playing SW Trends Long | EG3: TOTAL of Three Pillars | EH3: P/L per Trade | EI3: P/L Total | EJ3: P/L per Trade MOC | EK3: P/L MOC Total | EL3: R per Trade | EM3: R Total | EN3: R per Trade Up | EO3: R Total Up Trends | EP3: R per Trade SW | EQ3: R Total SW Trends | ER3: R per Trade Dwn | ES3: R Total Dwn Trends | ET3: R per Trade | EU3: R Total | EV3: R per Trade Up | EW3: R Total Up Trends | EX3: R per Trade SW | EY3: R Total SW Trends | EZ3: R per Trade Dwn | FA3: R Total Dwn Trends | FB3: R Dwn per Trade MOC | FC3: R Dwn MOC Total | FD3: R Dwn per Trade MOC | FE3: R Dwn MOC Total | FF3: R per Trade MOC | FG3: R MOC Total | FH3: R Dwn per Trade MOC | FI3: R Dwn MOC Total | FJ3: R per Trade MOC | FK3: R MOC Total | FL3: R Dwn per Trade MOC | FM3: R Dwn MOC Total | FN3: R per Trade MOC | FO3: R MOC Total | FP3: R per Trade | FQ3: R Total | FR3: OverallExp. | FS3: Exp 50-ma | FT3: Exp 25-ma | FU3: Variance Act v. Strat Total | FV3: Daily Trend | FW3: Trend Tracking | FX3: Gap Ups with trend | FY3: Gap Ups Against Trend | FZ3: Gap Ups NA | GA3: Theoretical Direction with trend and sideways going Long | GB3: Gap Dns with trend | GC3: Gap Dns Against Trend | GD3: Gap Dns NA | GE3: Entry | GF3: L / S | GG3: Entry Shares | GH3: Cost | GI3: Exit Shares | GJ3: Exit at Open or "Other" | GK3: P&L if Using MKT at Open or Other Exit | GL3: MOC P / L | GM3: Sw Trends MOC R | GN3: Total Sw Trends MOC R | GO3: UP Trends MOC R | GP3: Total UP Trends MOC R | GQ3: Dwn Trends MOC R | GR3: Total Dwn Trends MOC R | GS3: Sw Trends MOC P/L | GT3: Total Sw Trends MOC P/L | GU3: UP Trends MOC P/L | GV3: Total UP Trends MOC P/L | GW3: Dwn Trends MOC P/L | GX3: Total Dwn Trends MOC P/L | GY3: Total MOC P / L | GZ3: Exit Using MOC | HA3: Var vs. Strategy | HB3: Exit Type | HC3: Trade Exp | HD3: R per Trade | HE3: R Total | HF3: P/L Total | HG3: P/L per Trade | HH3: MOC R | HJ3: =AVERAGEIF($EH$4:$EH$448,">0") -> 49.334696 | HK3: =AVERAGEIF($EH$4:$EH$448,"<0") -> -45.175088 | HL3: =HJ3/-HK3 -> 1.0920775 | HM3: =(HN3*HJ3)+(HO3*HK3) -> 2530.0994 | HN3: =COUNTIF($EH$4:$EH$448,">0") -> 239 | HO3: =COUNTIF($EH$4:$EH$448,"<0") -> 205 | HP3: =HN3/(HN3+HO3) -> 0.53828829 | HQ3: =AVERAGEIF($FP$4:$FP$448,">0") -> 0.92852474 | HR3: =AVERAGEIF($FP$4:$FP$448,"<0") -> -0.74772978 | HS3: =HQ3/-HR3 -> 1.2417919 | HT3: =(HN3*HQ3)+(HR3*HO3) -> 68.632809 | HU3: =SUMIFS($FP$4:$FP$448,$H$4:$H$448,"o") -> 37.440139 | HV3: =SUMIFS($FP$4:$FP$448,$D$4:$D$448,"Y") -> 25.097747 | HW3: =SUMIFS($FP$4:$FP$448,$D$4:$D$448,"N") -> 43.535062 | HX3: =SUMIFS($FP$4:$FP$448,$D$4:$D$448,"Y")/COUNTIF($D$4:$D$448,"Y") -> 0.064353199 | HY3: =SUMIFS($FP$4:$FP$448,$D$4:$D$448,"N")/COUNTIF($D$4:$D$448,"N") -> 0.79154658 | HZ3: =COUNTIF($D$4:$D$448,"Y") -> 390 | IA3: =COUNTIF($D$4:$D$448,"N") -> 55
