Workbook

Sheet Indices
A1: Stock | B1: Index | C1: Index2 | D1: Sector | E1: As of: | F1: 45616
A2: NVDA | B2: SP500 | C2: NQ100
A3: AAPL | B3: SP500 | C3: NQ100
A4: MSFT | B4: SP500 | C4: NQ100
A5: GOOG | B5: SP500 | C5: NQ100
A6: GOOGL | B6: SP500 | C6: NQ100
A7: AMZN | B7: SP500 | C7: NQ100
A8: META | B8: SP500 | C8: NQ100
A9: TSLA | B9: SP500 | C9: NQ100
A10: BRK.B | B10: SP500
A11: AVGO | B11: SP500 | C11: NQ100
A12: WMT | B12: SP500
A13: JPM | B13: SP500
A14: LLY | B14: SP500
A15: V | B15: SP500
A16: UNH | B16: SP500
A17: XOM | B17: SP500
A18: ORCL | B18: SP500
A19: MA | B19: SP500
A20: COST | B20: SP500 | C20: NQ100
A21: PG | B21: SP500
A22: HD | B22: SP500
A23: NFLX | B23: SP500 | C23: NQ100
A24: JNJ | B24: SP500
A25: BAC | B25: SP500
A26: CRM | B26: SP500
A27: ABBV | B27: SP500
A28: CVX | B28: SP500
A29: TMUS | B29: SP500 | C29: NQ100
A30: KO | B30: SP500
A31: MRK | B31: SP500
A32: WFC | B32: SP500
A33: CSCO | B33: SP500 | C33: NQ100
A34: BX | B34: SP500
A35: ACN | B35: SP500
A36: AMD | B36: SP500 | C36: NQ100
A37: ADBE | B37: SP500 | C37: NQ100
A38: PEP | B38: SP500 | C38: NQ100
A39: LIN | B39: SP500 | C39: NQ100
A40: MS | B40: SP500
...

Sheet Industries
A1: Sector | B1: XLF | C1: XLE
A2: Industries | B2: Consumer Finance | C2: Oil & Gas Refining & Marketing
B3: Capital markets | C3: Integrated Oil & Gas
B4: Banks | C4: Oil & Gas Equipment & Services
B5: Financial Services | C5: Oil & Gas Exploration & Production
B6: Insurance | C6: Oil & Gas Storage & Transportation

Sheet Pivot
A1: Index | B1: (All)
A3: Row Labels | B3: Count of Ticker
A4: 1-Apr | B4: 11
A5: 2-Apr | B5: 17
A6: 3-Apr | B6: 12
A7: 4-Apr | B7: 3
A8: 7-Apr | B8: 33
A9: 8-Apr | B9: 29
A10: 9-Apr | B10: 25
A11: 10-Apr | B11: 20
A12: 11-Apr | B12: 28
A13: 14-Apr | B13: 11
A14: 15-Apr | B14: 32
A15: 16-Apr | B15: 44
... A59: Grand Total | B59: 4468

Sheet Charts

Sheet SPDR Chart
B1: % of Tot > | C1: =C2/SUM($C$2:$Q$2) -> 0.086705202 | D1: =D2/SUM($C$2:$Q$2) -> 0.17630058 | E1: =E2/SUM($C$2:$Q$2) -> 0.020231214 | F1: =F2/SUM($C$2:$Q$2) -> 0.11560694 | G1: =G2/SUM($C$2:$Q$2) -> 0.12427746 | H1: =H2/SUM($C$2:$Q$2) -> 0.037572254 | I1: =I2/SUM($C$2:$Q$2) -> 0 | J1: =J2/SUM($C$2:$Q$2) -> 0.11271676 | ... Q1: =Q2/SUM($C$2:$Q$2) -> 0.043352601 | R1: In SPY Total | S1: % | U1: % of Tot > | V1: =V2/SUM($C$2:$Q$2) -> 0.01734104 | W1: =W2/SUM($C$2:$Q$2) -> 0.011560694 | X1: =X2/SUM($C$2:$Q$2) -> 0.0028901734 | Y1: =Y2/SUM($C$2:$Q$2) -> 0.0086705202 | Z1: =Z2/SUM($C$2:$Q$2) -> 0.0057803468 | AA1: =AA2/SUM($C$2:$Q$2) -> 0 | AB1: =AB2/SUM($C$2:$Q$2) -> 0 | AC1: =AC2/SUM($C$2:$Q$2) -> 0.031791908 | ... AJ1: =AJ2/SUM($C$2:$Q$2) -> 0.083815029 | AK1: Total | AL1: %
B2: SPY # > | C2: =SUM(C4:C86) -> 30 | D2: =SUM(D4:D86) -> 61 | E2: =SUM(E4:E86) -> 7 | F2: =SUM(F4:F86) -> 40 | G2: =SUM(G4:G86) -> 43 | H2: =SUM(H4:H86) -> 13 | I2: =SUM(I4:I86) -> 0 | J2: =SUM(J4:J86) -> 39 | ... Q2: =SUM(Q4:Q86) -> 15 | U2: Not Spy# > | V2: =SUM(V4:V86) -> 6 | W2: =SUM(W4:W86) -> 4 | X2: =SUM(X4:X86) -> 1 | Y2: =SUM(Y4:Y86) -> 3 | Z2: =SUM(Z4:Z86) -> 2 | AA2: =SUM(AA4:AA86) -> 0 | AB2: =SUM(AB4:AB86) -> 0 | AC2: =SUM(AC4:AC86) -> 11 | ... AJ2: =SUM(AJ4:AJ86) -> 29
B3: Sector > | C3: XLP | D3: XLI | E3: XHB | F3: XLF | G3: XLV | H3: XLE | I3: XLRE | J3: XLY | K3: XLC | L3: XLK | M3: XLB | N3: XLU | O3: SMH | P3: INS | Q3: IGV | U3: Sector > | V3: XLP | W3: XLI | X3: XHB | Y3: XLF | Z3: XLV | AA3: XLE | AB3: XLRE | AC3: XLY | AD3: XLC | AE3: XLK | AF3: XLB | AG3: XLU | AH3: SMH | AI3: INS | AJ3: IGV
B4: 45756 | C4: =COUNTIFS('2025-Q2'!$E$4:$E$422,'SPDR Chart'!C$3,'2025-Q2'!$F$4:$F$422,'SPDR Chart'!$B4,'2025-Q2'!$D$4:$D$422,"Y") -> 1 | D4: =COUNTIFS('2025-Q2'!$E$4:$E$422,'SPDR Chart'!D$3,'2025-Q2'!$F$4:$F$422,'SPDR Chart'!$B4,'2025-Q2'!$D$4:$D$422,"Y") -> 1 | E4: =COUNTIFS('2025-Q2'!$E$4:$E$422,'SPDR Chart'!E$3,'2025-Q2'!$F$4:$F$422,'SPDR Chart'!$B4,'2025-Q2'!$D$4:$D$422,"Y") -> 0 | F4: =COUNTIFS('2025-Q2'!$E$4:$E$422,'SPDR Chart'!F$3,'2025-Q2'!$F$4:$F$422,'SPDR Chart'!$B4,'2025-Q2'!$D$4:$D$422,"Y") -> 0 | G4: =COUNTIFS('2025-Q2'!$E$4:$E$422,'SPDR Chart'!G$3,'2025-Q2'!$F$4:$F$422,'SPDR Chart'!$B4,'2025-Q2'!$D$4:$D$422,"Y") -> 0 | H4: =COUNTIFS('2025-Q2'!$E$4:$E$422,'SPDR Chart'!H$3,'2025-Q2'!$F$4:$F$422,'SPDR Chart'!$B4,'2025-Q2'!$D$4:$D$422,"Y") -> 0 | I4: =COUNTIFS('2025-Q2'!$E$4:$E$422,'SPDR Chart'!I$3,'2025-Q2'!$F$4:$F$422,'SPDR Chart'!$B4,'2025-Q2'!$D$4:$D$422,"Y") -> 0 | J4: =COUNTIFS('2025-Q2'!$E$4:$E$422,'SPDR Chart'!J$3,'2025-Q2'!$F$4:$F$422,'SPDR Chart'!$B4,'2025-Q2'!$D$4:$D$422,"Y") -> 0 | ... Q4: =COUNTIFS('2025-Q2'!$E$4:$E$422,'SPDR Chart'!Q$3,'2025-Q2'!$F$4:$F$422,'SPDR Chart'!$B4,'2025-Q2'!$D$4:$D$422,"Y") -> 0 | R4: =SUM(C4:Q4) -> 2 | S4: =SUM($R$4:R4)/SUM($R$4:$R$86) -> 0.0057803468 | U4: 45756 | V4: =COUNTIFS('2025-Q2'!$E$4:$E$422,'SPDR Chart'!V$3,'2025-Q2'!$F$4:$F$422,'SPDR Chart'!$B4,'2025-Q2'!$D$4:$D$422,"N") -> 0 | W4: =COUNTIFS('2025-Q2'!$E$4:$E$422,'SPDR Chart'!W$3,'2025-Q2'!$F$4:$F$422,'SPDR Chart'!$B4,'2025-Q2'!$D$4:$D$422,"N") -> 0 | X4: =COUNTIFS('2025-Q2'!$E$4:$E$422,'SPDR Chart'!X$3,'2025-Q2'!$F$4:$F$422,'SPDR Chart'!$B4,'2025-Q2'!$D$4:$D$422,"N") -> 0 | Y4: =COUNTIFS('2025-Q2'!$E$4:$E$422,'SPDR Chart'!Y$3,'2025-Q2'!$F$4:$F$422,'SPDR Chart'!$B4,'2025-Q2'!$D$4:$D$422,"N") -> 0 | Z4: =COUNTIFS('2025-Q2'!$E$4:$E$422,'SPDR Chart'!Z$3,'2025-Q2'!$F$4:$F$422,'SPDR Chart'!$B4,'2025-Q2'!$D$4:$D$422,"N") -> 0 | AA4: =COUNTIFS('2025-Q2'!$E$4:$E$422,'SPDR Chart'!AA$3,'2025-Q2'!$F$4:$F$422,'SPDR Chart'!$B4,'2025-Q2'!$D$4:$D$422,"N") -> 0 | AB4: =COUNTIFS('2025-Q2'!$E$4:$E$422,'SPDR Chart'!AB$3,'2025-Q2'!$F$4:$F$422,'SPDR Chart'!$B4,'2025-Q2'!$D$4:$D$422,"N") -> 0 | AC4: =COUNTIFS('2025-Q2'!$E$4:$E$422,'SPDR Chart'!AC$3,'2025-Q2'!$F$4:$F$422,'SPDR Chart'!$B4,'2025-Q2'!$D$4:$D$422,"N") -> 0 | ... AJ4: =COUNTIFS('2025-Q2'!$E$4:$E$422,'SPDR Chart'!AJ$3,'2025-Q2'!$F$4:$F$422,'SPDR Chart'!$B4,'2025-Q2'!$D$4:$D$422,"N") -> 0 | AK4: =SUM(V4:AJ4) -> 0 | AL4: =SUM($AK$4:AK4)/SUM($AK$4:$AK$86) -> 0
B5: 45757 | C5: =COUNTIFS('2025-Q2'!$E$4:$E$422,'SPDR Chart'!C$3,'2025-Q2'!$F$4:$F$422,'SPDR Chart'!$B5,'2025-Q2'!$D$4:$D$422,"Y") -> 0 | D5: =COUNTIFS('2025-Q2'!$E$4:$E$422,'SPDR Chart'!D$3,'2025-Q2'!$F$4:$F$422,'SPDR Chart'!$B5,'2025-Q2'!$D$4:$D$422,"Y") -> 0 | E5: =COUNTIFS('2025-Q2'!$E$4:$E$422,'SPDR Chart'!E$3,'2025-Q2'!$F$4:$F$422,'SPDR Chart'!$B5,'2025-Q2'!$D$4:$D$422,"Y") -> 0 | F5: =COUNTIFS('2025-Q2'!$E$4:$E$422,'SPDR Chart'!F$3,'2025-Q2'!$F$4:$F$422,'SPDR Chart'!$B5,'2025-Q2'!$D$4:$D$422,"Y") -> 0 | G5: =COUNTIFS('2025-Q2'!$E$4:$E$422,'SPDR Chart'!G$3,'2025-Q2'!$F$4:$F$422,'SPDR Chart'!$B5,'2025-Q2'!$D$4:$D$422,"Y") -> 0 | H5: =COUNTIFS('2025-Q2'!$E$4:$E$422,'SPDR Chart'!H$3,'2025-Q2'!$F$4:$F$422,'SPDR Chart'!$B5,'2025-Q2'!$D$4:$D$422,"Y") -> 0 | I5: =COUNTIFS('2025-Q2'!$E$4:$E$422,'SPDR Chart'!I$3,'2025-Q2'!$F$4:$F$422,'SPDR Chart'!$B5,'2025-Q2'!$D$4:$D$422,"Y") -> 0 | J5: =COUNTIFS('2025-Q2'!$E$4:$E$422,'SPDR Chart'!J$3,'2025-Q2'!$F$4:$F$422,'SPDR Chart'!$B5,'2025-Q2'!$D$4:$D$422,"Y") -> 0 | ... Q5: =COUNTIFS('2025-Q2'!$E$4:$E$422,'SPDR Chart'!Q$3,'2025-Q2'!$F$4:$F$422,'SPDR Chart'!$B5,'2025-Q2'!$D$4:$D$422,"Y") -> 0 | R5: =SUM(C5:Q5) -> 0 | S5: =SUM($R$4:R5)/SUM($R$4:$R$86) -> 0.0057803468 | U5: 45757 | V5: =COUNTIFS('2025-Q2'!$E$4:$E$422,'SPDR Chart'!V$3,'2025-Q2'!$F$4:$F$422,'SPDR Chart'!$B5,'2025-Q2'!$D$4:$D$422,"N") -> 0 | W5: =COUNTIFS('2025-Q2'!$E$4:$E$422,'SPDR Chart'!W$3,'2025-Q2'!$F$4:$F$422,'SPDR Chart'!$B5,'2025-Q2'!$D$4:$D$422,"N") -> 0 | X5: =COUNTIFS('2025-Q2'!$E$4:$E$422,'SPDR Chart'!X$3,'2025-Q2'!$F$4:$F$422,'SPDR Chart'!$B5,'2025-Q2'!$D$4:$D$422,"N") -> 0 | Y5: =COUNTIFS('2025-Q2'!$E$4:$E$422,'SPDR Chart'!Y$3,'2025-Q2'!$F$4:$F$422,'SPDR Chart'!$B5,'2025-Q2'!$D$4:$D$422,"N") -> 0 | Z5: =COUNTIFS('2025-Q2'!$E$4:$E$422,'SPDR Chart'!Z$3,'2025-Q2'!$F$4:$F$422,'SPDR Chart'!$B5,'2025-Q2'!$D$4:$D$422,"N") -> 0 | AA5: =COUNTIFS('2025-Q2'!$E$4:$E$422,'SPDR Chart'!AA$3,'2025-Q2'!$F$4:$F$422,'SPDR Chart'!$B5,'2025-Q2'!$D$4:$D$422,"N") -> 0 | AB5: =COUNTIFS('2025-Q2'!$E$4:$E$422,'SPDR Chart'!AB$3,'2025-Q2'!$F$4:$F$422,'SPDR Chart'!$B5,'2025-Q2'!$D$4:$D$422,"N") -> 0 | AC5: =COUNTIFS('2025-Q2'!$E$4:$E$422,'SPDR Chart'!AC$3,'2025-Q2'!$F$4:$F$422,'SPDR Chart'!$B5,'2025-Q2'!$D$4:$D$422,"N") -> 0 | ... AJ5: =COUNTIFS('2025-Q2'!$E$4:$E$422,'SPDR Chart'!AJ$3,'2025-Q2'!$F$4:$F$422,'SPDR Chart'!$B5,'2025-Q2'!$D$4:$D$422,"N") -> 0 | AK5: =SUM(V5:AJ5) -> 0 | AL5: =SUM($AK$4:AK5)/SUM($AK$4:$AK$86) -> 0
B6: 45758 | C6: =COUNTIFS('2025-Q2'!$E$4:$E$422,'SPDR Chart'!C$3,'2025-Q2'!$F$4:$F$422,'SPDR Chart'!$B6,'2025-Q2'!$D$4:$D$422,"Y") -> 0 | D6: =COUNTIFS('2025-Q2'!$E$4:$E$422,'SPDR Chart'!D$3,'2025-Q2'!$F$4:$F$422,'SPDR Chart'!$B6,'2025-Q2'!$D$4:$D$422,"Y") -> 1 | E6: =COUNTIFS('2025-Q2'!$E$4:$E$422,'SPDR Chart'!E$3,'2025-Q2'!$F$4:$F$422,'SPDR Chart'!$B6,'2025-Q2'!$D$4:$D$422,"Y") -> 0 | F6: =COUNTIFS('2025-Q2'!$E$4:$E$422,'SPDR Chart'!F$3,'2025-Q2'!$F$4:$F$422,'SPDR Chart'!$B6,'2025-Q2'!$D$4:$D$422,"Y") -> 5 | G6: =COUNTIFS('2025-Q2'!$E$4:$E$422,'SPDR Chart'!G$3,'2025-Q2'!$F$4:$F$422,'SPDR Chart'!$B6,'2025-Q2'!$D$4:$D$422,"Y") -> 0 | H6: =COUNTIFS('2025-Q2'!$E$4:$E$422,'SPDR Chart'!H$3,'2025-Q2'!$F$4:$F$422,'SPDR Chart'!$B6,'2025-Q2'!$D$4:$D$422,"Y") -> 0 | I6: =COUNTIFS('2025-Q2'!$E$4:$E$422,'SPDR Chart'!I$3,'2025-Q2'!$F$4:$F$422,'SPDR Chart'!$B6,'2025-Q2'!$D$4:$D$422,"Y") -> 0 | J6: =COUNTIFS('2025-Q2'!$E$4:$E$422,'SPDR Chart'!J$3,'2025-Q2'!$F$4:$F$422,'SPDR Chart'!$B6,'2025-Q2'!$D$4:$D$422,"Y") -> 0 | ... Q6: =COUNTIFS('2025-Q2'!$E$4:$E$422,'SPDR Chart'!Q$3,'2025-Q2'!$F$4:$F$422,'SPDR Chart'!$B6,'2025-Q2'!$D$4:$D$422,"Y") -> 0 | R6: =SUM(C6:Q6) -> 6 | S6: =SUM($R$4:R6)/SUM($R$4:$R$86) -> 0.023121387 | U6: 45758 | V6: =COUNTIFS('2025-Q2'!$E$4:$E$422,'SPDR Chart'!V$3,'2025-Q2'!$F$4:$F$422,'SPDR Chart'!$B6,'2025-Q2'!$D$4:$D$422,"N") -> 0 | W6: =COUNTIFS('2025-Q2'!$E$4:$E$422,'SPDR Chart'!W$3,'2025-Q2'!$F$4:$F$422,'SPDR Chart'!$B6,'2025-Q2'!$D$4:$D$422,"N") -> 0 | X6: =COUNTIFS('2025-Q2'!$E$4:$E$422,'SPDR Chart'!X$3,'2025-Q2'!$F$4:$F$422,'SPDR Chart'!$B6,'2025-Q2'!$D$4:$D$422,"N") -> 0 | Y6: =COUNTIFS('2025-Q2'!$E$4:$E$422,'SPDR Chart'!Y$3,'2025-Q2'!$F$4:$F$422,'SPDR Chart'!$B6,'2025-Q2'!$D$4:$D$422,"N") -> 0 | Z6: =COUNTIFS('2025-Q2'!$E$4:$E$422,'SPDR Chart'!Z$3,'2025-Q2'!$F$4:$F$422,'SPDR Chart'!$B6,'2025-Q2'!$D$4:$D$422,"N") -> 0 | AA6: =COUNTIFS('2025-Q2'!$E$4:$E$422,'SPDR Chart'!AA$3,'2025-Q2'!$F$4:$F$422,'SPDR Chart'!$B6,'2025-Q2'!$D$4:$D$422,"N") -> 0 | AB6: =COUNTIFS('2025-Q2'!$E$4:$E$422,'SPDR Chart'!AB$3,'2025-Q2'!$F$4:$F$422,'SPDR Chart'!$B6,'2025-Q2'!$D$4:$D$422,"N") -> 0 | AC6: =COUNTIFS('2025-Q2'!$E$4:$E$422,'SPDR Chart'!AC$3,'2025-Q2'!$F$4:$F$422,'SPDR Chart'!$B6,'2025-Q2'!$D$4:$D$422,"N") -> 0 | ... AJ6: =COUNTIFS('2025-Q2'!$E$4:$E$422,'SPDR Chart'!AJ$3,'2025-Q2'!$F$4:$F$422,'SPDR Chart'!$B6,'2025-Q2'!$D$4:$D$422,"N") -> 0 | AK6: =SUM(V6:AJ6) -> 0 | AL6: =SUM($AK$4:AK6)/SUM($AK$4:$AK$86) -> 0
B7: 45759 | C7: =COUNTIFS('2025-Q2'!$E$4:$E$422,'SPDR Chart'!C$3,'2025-Q2'!$F$4:$F$422,'SPDR Chart'!$B7,'2025-Q2'!$D$4:$D$422,"Y") -> 0 | D7: =COUNTIFS('2025-Q2'!$E$4:$E$422,'SPDR Chart'!D$3,'2025-Q2'!$F$4:$F$422,'SPDR Chart'!$B7,'2025-Q2'!$D$4:$D$422,"Y") -> 0 | E7: =COUNTIFS('2025-Q2'!$E$4:$E$422,'SPDR Chart'!E$3,'2025-Q2'!$F$4:$F$422,'SPDR Chart'!$B7,'2025-Q2'!$D$4:$D$422,"Y") -> 0 | F7: =COUNTIFS('2025-Q2'!$E$4:$E$422,'SPDR Chart'!F$3,'2025-Q2'!$F$4:$F$422,'SPDR Chart'!$B7,'2025-Q2'!$D$4:$D$422,"Y") -> 0 | G7: =COUNTIFS('2025-Q2'!$E$4:$E$422,'SPDR Chart'!G$3,'2025-Q2'!$F$4:$F$422,'SPDR Chart'!$B7,'2025-Q2'!$D$4:$D$422,"Y") -> 0 | H7: =COUNTIFS('2025-Q2'!$E$4:$E$422,'SPDR Chart'!H$3,'2025-Q2'!$F$4:$F$422,'SPDR Chart'!$B7,'2025-Q2'!$D$4:$D$422,"Y") -> 0 | I7: =COUNTIFS('2025-Q2'!$E$4:$E$422,'SPDR Chart'!I$3,'2025-Q2'!$F$4:$F$422,'SPDR Chart'!$B7,'2025-Q2'!$D$4:$D$422,"Y") -> 0 | J7: =COUNTIFS('2025-Q2'!$E$4:$E$422,'SPDR Chart'!J$3,'2025-Q2'!$F$4:$F$422,'SPDR Chart'!$B7,'2025-Q2'!$D$4:$D$422,"Y") -> 0 | ... Q7: =COUNTIFS('2025-Q2'!$E$4:$E$422,'SPDR Chart'!Q$3,'2025-Q2'!$F$4:$F$422,'SPDR Chart'!$B7,'2025-Q2'!$D$4:$D$422,"Y") -> 0 | R7: =SUM(C7:Q7) -> 0 | S7: =SUM($R$4:R7)/SUM($R$4:$R$86) -> 0.023121387 | U7: 45759 | V7: =COUNTIFS('2025-Q2'!$E$4:$E$422,'SPDR Chart'!V$3,'2025-Q2'!$F$4:$F$422,'SPDR Chart'!$B7,'2025-Q2'!$D$4:$D$422,"N") -> 0 | W7: =COUNTIFS('2025-Q2'!$E$4:$E$422,'SPDR Chart'!W$3,'2025-Q2'!$F$4:$F$422,'SPDR Chart'!$B7,'2025-Q2'!$D$4:$D$422,"N") -> 0 | X7: =COUNTIFS('2025-Q2'!$E$4:$E$422,'SPDR Chart'!X$3,'2025-Q2'!$F$4:$F$422,'SPDR Chart'!$B7,'2025-Q2'!$D$4:$D$422,"N") -> 0 | Y7: =COUNTIFS('2025-Q2'!$E$4:$E$422,'SPDR Chart'!Y$3,'2025-Q2'!$F$4:$F$422,'SPDR Chart'!$B7,'2025-Q2'!$D$4:$D$422,"N") -> 0 | Z7: =COUNTIFS('2025-Q2'!$E$4:$E$422,'SPDR Chart'!Z$3,'2025-Q2'!$F$4:$F$422,'SPDR Chart'!$B7,'2025-Q2'!$D$4:$D$422,"N") -> 0 | AA7: =COUNTIFS('2025-Q2'!$E$4:$E$422,'SPDR Chart'!AA$3,'2025-Q2'!$F$4:$F$422,'SPDR Chart'!$B7,'2025-Q2'!$D$4:$D$422,"N") -> 0 | AB7: =COUNTIFS('2025-Q2'!$E$4:$E$422,'SPDR Chart'!AB$3,'2025-Q2'!$F$4:$F$422,'SPDR Chart'!$B7,'2025-Q2'!$D$4:$D$422,"N") -> 0 | AC7: =COUNTIFS('2025-Q2'!$E$4:$E$422,'SPDR Chart'!AC$3,'2025-Q2'!$F$4:$F$422,'SPDR Chart'!$B7,'2025-Q2'!$D$4:$D$422,"N") -> 0 | ... AJ7: =COUNTIFS('2025-Q2'!$E$4:$E$422,'SPDR Chart'!AJ$3,'2025-Q2'!$F$4:$F$422,'SPDR Chart'!$B7,'2025-Q2'!$D$4:$D$422,"N") -> 0 | AK7: =SUM(V7:AJ7) -> 0 | AL7: =SUM($AK$4:AK7)/SUM($AK$4:$AK$86) -> 0
B8: 45760 | C8: =COUNTIFS('2025-Q2'!$E$4:$E$422,'SPDR Chart'!C$3,'2025-Q2'!$F$4:$F$422,'SPDR Chart'!$B8,'2025-Q2'!$D$4:$D$422,"Y") -> 0 | D8: =COUNTIFS('2025-Q2'!$E$4:$E$422,'SPDR Chart'!D$3,'2025-Q2'!$F$4:$F$422,'SPDR Chart'!$B8,'2025-Q2'!$D$4:$D$422,"Y") -> 0 | E8: =COUNTIFS('2025-Q2'!$E$4:$E$422,'SPDR Chart'!E$3,'2025-Q2'!$F$4:$F$422,'SPDR Chart'!$B8,'2025-Q2'!$D$4:$D$422,"Y") -> 0 | F8: =COUNTIFS('2025-Q2'!$E$4:$E$422,'SPDR Chart'!F$3,'2025-Q2'!$F$4:$F$422,'SPDR Chart'!$B8,'2025-Q2'!$D$4:$D$422,"Y") -> 0 | G8: =COUNTIFS('2025-Q2'!$E$4:$E$422,'SPDR Chart'!G$3,'2025-Q2'!$F$4:$F$422,'SPDR Chart'!$B8,'2025-Q2'!$D$4:$D$422,"Y") -> 0 | H8: =COUNTIFS('2025-Q2'!$E$4:$E$422,'SPDR Chart'!H$3,'2025-Q2'!$F$4:$F$422,'SPDR Chart'!$B8,'2025-Q2'!$D$4:$D$422,"Y") -> 0 | I8: =COUNTIFS('2025-Q2'!$E$4:$E$422,'SPDR Chart'!I$3,'2025-Q2'!$F$4:$F$422,'SPDR Chart'!$B8,'2025-Q2'!$D$4:$D$422,"Y") -> 0 | J8: =COUNTIFS('2025-Q2'!$E$4:$E$422,'SPDR Chart'!J$3,'2025-Q2'!$F$4:$F$422,'SPDR Chart'!$B8,'2025-Q2'!$D$4:$D$422,"Y") -> 0 | ... Q8: =COUNTIFS('2025-Q2'!$E$4:$E$422,'SPDR Chart'!Q$3,'2025-Q2'!$F$4:$F$422,'SPDR Chart'!$B8,'2025-Q2'!$D$4:$D$422,"Y") -> 0 | R8: =SUM(C8:Q8) -> 0 | S8: =SUM($R$4:R8)/SUM($R$4:$R$86) -> 0.023121387 | U8: 45760 | V8: =COUNTIFS('2025-Q2'!$E$4:$E$422,'SPDR Chart'!V$3,'2025-Q2'!$F$4:$F$422,'SPDR Chart'!$B8,'2025-Q2'!$D$4:$D$422,"N") -> 0 | W8: =COUNTIFS('2025-Q2'!$E$4:$E$422,'SPDR Chart'!W$3,'2025-Q2'!$F$4:$F$422,'SPDR Chart'!$B8,'2025-Q2'!$D$4:$D$422,"N") -> 0 | X8: =COUNTIFS('2025-Q2'!$E$4:$E$422,'SPDR Chart'!X$3,'2025-Q2'!$F$4:$F$422,'SPDR Chart'!$B8,'2025-Q2'!$D$4:$D$422,"N") -> 0 | Y8: =COUNTIFS('2025-Q2'!$E$4:$E$422,'SPDR Chart'!Y$3,'2025-Q2'!$F$4:$F$422,'SPDR Chart'!$B8,'2025-Q2'!$D$4:$D$422,"N") -> 0 | Z8: =COUNTIFS('2025-Q2'!$E$4:$E$422,'SPDR Chart'!Z$3,'2025-Q2'!$F$4:$F$422,'SPDR Chart'!$B8,'2025-Q2'!$D$4:$D$422,"N") -> 0 | AA8: =COUNTIFS('2025-Q2'!$E$4:$E$422,'SPDR Chart'!AA$3,'2025-Q2'!$F$4:$F$422,'SPDR Chart'!$B8,'2025-Q2'!$D$4:$D$422,"N") -> 0 | AB8: =COUNTIFS('2025-Q2'!$E$4:$E$422,'SPDR Chart'!AB$3,'2025-Q2'!$F$4:$F$422,'SPDR Chart'!$B8,'2025-Q2'!$D$4:$D$422,"N") -> 0 | AC8: =COUNTIFS('2025-Q2'!$E$4:$E$422,'SPDR Chart'!AC$3,'2025-Q2'!$F$4:$F$422,'SPDR Chart'!$B8,'2025-Q2'!$D$4:$D$422,"N") -> 0 | ... AJ8: =COUNTIFS('2025-Q2'!$E$4:$E$422,'SPDR Chart'!AJ$3,'2025-Q2'!$F$4:$F$422,'SPDR Chart'!$B8,'2025-Q2'!$D$4:$D$422,"N") -> 0 | AK8: =SUM(V8:AJ8) -> 0 | AL8: =SUM($AK$4:AK8)/SUM($AK$4:$AK$86) -> 0
B9: 45761 | C9: =COUNTIFS('2025-Q2'!$E$4:$E$422,'SPDR Chart'!C$3,'2025-Q2'!$F$4:$F$422,'SPDR Chart'!$B9,'2025-Q2'!$D$4:$D$422,"Y") -> 0 | D9: =COUNTIFS('2025-Q2'!$E$4:$E$422,'SPDR Chart'!D$3,'2025-Q2'!$F$4:$F$422,'SPDR Chart'!$B9,'2025-Q2'!$D$4:$D$422,"Y") -> 0 | E9: =COUNTIFS('2025-Q2'!$E$4:$E$422,'SPDR Chart'!E$3,'2025-Q2'!$F$4:$F$422,'SPDR Chart'!$B9,'2025-Q2'!$D$4:$D$422,"Y") -> 0 | F9: =COUNTIFS('2025-Q2'!$E$4:$E$422,'SPDR Chart'!F$3,'2025-Q2'!$F$4:$F$422,'SPDR Chart'!$B9,'2025-Q2'!$D$4:$D$422,"Y") -> 2 | G9: =COUNTIFS('2025-Q2'!$E$4:$E$422,'SPDR Chart'!G$3,'2025-Q2'!$F$4:$F$422,'SPDR Chart'!$B9,'2025-Q2'!$D$4:$D$422,"Y") -> 0 | H9: =COUNTIFS('2025-Q2'!$E$4:$E$422,'SPDR Chart'!H$3,'2025-Q2'!$F$4:$F$422,'SPDR Chart'!$B9,'2025-Q2'!$D$4:$D$422,"Y") -> 0 | I9: =COUNTIFS('2025-Q2'!$E$4:$E$422,'SPDR Chart'!I$3,'2025-Q2'!$F$4:$F$422,'SPDR Chart'!$B9,'2025-Q2'!$D$4:$D$422,"Y") -> 0 | J9: =COUNTIFS('2025-Q2'!$E$4:$E$422,'SPDR Chart'!J$3,'2025-Q2'!$F$4:$F$422,'SPDR Chart'!$B9,'2025-Q2'!$D$4:$D$422,"Y") -> 0 | ... Q9: =COUNTIFS('2025-Q2'!$E$4:$E$422,'SPDR Chart'!Q$3,'2025-Q2'!$F$4:$F$422,'SPDR Chart'!$B9,'2025-Q2'!$D$4:$D$422,"Y") -> 0 | R9: =SUM(C9:Q9) -> 2 | S9: =SUM($R$4:R9)/SUM($R$4:$R$86) -> 0.028901734 | U9: 45761 | V9: =COUNTIFS('2025-Q2'!$E$4:$E$422,'SPDR Chart'!V$3,'2025-Q2'!$F$4:$F$422,'SPDR Chart'!$B9,'2025-Q2'!$D$4:$D$422,"N") -> 0 | W9: =COUNTIFS('2025-Q2'!$E$4:$E$422,'SPDR Chart'!W$3,'2025-Q2'!$F$4:$F$422,'SPDR Chart'!$B9,'2025-Q2'!$D$4:$D$422,"N") -> 0 | X9: =COUNTIFS('2025-Q2'!$E$4:$E$422,'SPDR Chart'!X$3,'2025-Q2'!$F$4:$F$422,'SPDR Chart'!$B9,'2025-Q2'!$D$4:$D$422,"N") -> 0 | Y9: =COUNTIFS('2025-Q2'!$E$4:$E$422,'SPDR Chart'!Y$3,'2025-Q2'!$F$4:$F$422,'SPDR Chart'!$B9,'2025-Q2'!$D$4:$D$422,"N") -> 0 | Z9: =COUNTIFS('2025-Q2'!$E$4:$E$422,'SPDR Chart'!Z$3,'2025-Q2'!$F$4:$F$422,'SPDR Chart'!$B9,'2025-Q2'!$D$4:$D$422,"N") -> 0 | AA9: =COUNTIFS('2025-Q2'!$E$4:$E$422,'SPDR Chart'!AA$3,'2025-Q2'!$F$4:$F$422,'SPDR Chart'!$B9,'2025-Q2'!$D$4:$D$422,"N") -> 0 | AB9: =COUNTIFS('2025-Q2'!$E$4:$E$422,'SPDR Chart'!AB$3,'2025-Q2'!$F$4:$F$422,'SPDR Chart'!$B9,'2025-Q2'!$D$4:$D$422,"N") -> 0 | AC9: =COUNTIFS('2025-Q2'!$E$4:$E$422,'SPDR Chart'!AC$3,'2025-Q2'!$F$4:$F$422,'SPDR Chart'!$B9,'2025-Q2'!$D$4:$D$422,"N") -> 0 | ... AJ9: =COUNTIFS('2025-Q2'!$E$4:$E$422,'SPDR Chart'!AJ$3,'2025-Q2'!$F$4:$F$422,'SPDR Chart'!$B9,'2025-Q2'!$D$4:$D$422,"N") -> 0 | AK9: =SUM(V9:AJ9) -> 0 | AL9: =SUM($AK$4:AK9)/SUM($AK$4:$AK$86) -> 0
B10: 45762 | C10: =COUNTIFS('2025-Q2'!$E$4:$E$422,'SPDR Chart'!C$3,'2025-Q2'!$F$4:$F$422,'SPDR Chart'!$B10,'2025-Q2'!$D$4:$D$422,"Y") -> 0 | D10: =COUNTIFS('2025-Q2'!$E$4:$E$422,'SPDR Chart'!D$3,'2025-Q2'!$F$4:$F$422,'SPDR Chart'!$B10,'2025-Q2'!$D$4:$D$422,"Y") -> 2 | E10: =COUNTIFS('2025-Q2'!$E$4:$E$422,'SPDR Chart'!E$3,'2025-Q2'!$F$4:$F$422,'SPDR Chart'!$B10,'2025-Q2'!$D$4:$D$422,"Y") -> 0 | F10: =COUNTIFS('2025-Q2'!$E$4:$E$422,'SPDR Chart'!F$3,'2025-Q2'!$F$4:$F$422,'SPDR Chart'!$B10,'2025-Q2'!$D$4:$D$422,"Y") -> 3 | G10: =COUNTIFS('2025-Q2'!$E$4:$E$422,'SPDR Chart'!G$3,'2025-Q2'!$F$4:$F$422,'SPDR Chart'!$B10,'2025-Q2'!$D$4:$D$422,"Y") -> 1 | H10: =COUNTIFS('2025-Q2'!$E$4:$E$422,'SPDR Chart'!H$3,'2025-Q2'!$F$4:$F$422,'SPDR Chart'!$B10,'2025-Q2'!$D$4:$D$422,"Y") -> 0 | I10: =COUNTIFS('2025-Q2'!$E$4:$E$422,'SPDR Chart'!I$3,'2025-Q2'!$F$4:$F$422,'SPDR Chart'!$B10,'2025-Q2'!$D$4:$D$422,"Y") -> 0 | J10: =COUNTIFS('2025-Q2'!$E$4:$E$422,'SPDR Chart'!J$3,'2025-Q2'!$F$4:$F$422,'SPDR Chart'!$B10,'2025-Q2'!$D$4:$D$422,"Y") -> 0 | ... Q10: =COUNTIFS('2025-Q2'!$E$4:$E$422,'SPDR Chart'!Q$3,'2025-Q2'!$F$4:$F$422,'SPDR Chart'!$B10,'2025-Q2'!$D$4:$D$422,"Y") -> 0 | R10: =SUM(C10:Q10) -> 7 | S10: =SUM($R$4:R10)/SUM($R$4:$R$86) -> 0.049132948 | U10: 45762 | V10: =COUNTIFS('2025-Q2'!$E$4:$E$422,'SPDR Chart'!V$3,'2025-Q2'!$F$4:$F$422,'SPDR Chart'!$B10,'2025-Q2'!$D$4:$D$422,"N") -> 0 | W10: =COUNTIFS('2025-Q2'!$E$4:$E$422,'SPDR Chart'!W$3,'2025-Q2'!$F$4:$F$422,'SPDR Chart'!$B10,'2025-Q2'!$D$4:$D$422,"N") -> 0 | X10: =COUNTIFS('2025-Q2'!$E$4:$E$422,'SPDR Chart'!X$3,'2025-Q2'!$F$4:$F$422,'SPDR Chart'!$B10,'2025-Q2'!$D$4:$D$422,"N") -> 0 | Y10: =COUNTIFS('2025-Q2'!$E$4:$E$422,'SPDR Chart'!Y$3,'2025-Q2'!$F$4:$F$422,'SPDR Chart'!$B10,'2025-Q2'!$D$4:$D$422,"N") -> 0 | Z10: =COUNTIFS('2025-Q2'!$E$4:$E$422,'SPDR Chart'!Z$3,'2025-Q2'!$F$4:$F$422,'SPDR Chart'!$B10,'2025-Q2'!$D$4:$D$422,"N") -> 0 | AA10: =COUNTIFS('2025-Q2'!$E$4:$E$422,'SPDR Chart'!AA$3,'2025-Q2'!$F$4:$F$422,'SPDR Chart'!$B10,'2025-Q2'!$D$4:$D$422,"N") -> 0 | AB10: =COUNTIFS('2025-Q2'!$E$4:$E$422,'SPDR Chart'!AB$3,'2025-Q2'!$F$4:$F$422,'SPDR Chart'!$B10,'2025-Q2'!$D$4:$D$422,"N") -> 0 | AC10: =COUNTIFS('2025-Q2'!$E$4:$E$422,'SPDR Chart'!AC$3,'2025-Q2'!$F$4:$F$422,'SPDR Chart'!$B10,'2025-Q2'!$D$4:$D$422,"N") -> 0 | ... AJ10: =COUNTIFS('2025-Q2'!$E$4:$E$422,'SPDR Chart'!AJ$3,'2025-Q2'!$F$4:$F$422,'SPDR Chart'!$B10,'2025-Q2'!$D$4:$D$422,"N") -> 0 | AK10: =SUM(V10:AJ10) -> 0 | AL10: =SUM($AK$4:AK10)/SUM($AK$4:$AK$86) -> 0
B11: 45763 | C11: =COUNTIFS('2025-Q2'!$E$4:$E$422,'SPDR Chart'!C$3,'2025-Q2'!$F$4:$F$422,'SPDR Chart'!$B11,'2025-Q2'!$D$4:$D$422,"Y") -> 0 | D11: =COUNTIFS('2025-Q2'!$E$4:$E$422,'SPDR Chart'!D$3,'2025-Q2'!$F$4:$F$422,'SPDR Chart'!$B11,'2025-Q2'!$D$4:$D$422,"Y") -> 1 | E11: =COUNTIFS('2025-Q2'!$E$4:$E$422,'SPDR Chart'!E$3,'2025-Q2'!$F$4:$F$422,'SPDR Chart'!$B11,'2025-Q2'!$D$4:$D$422,"Y") -> 0 | F11: =COUNTIFS('2025-Q2'!$E$4:$E$422,'SPDR Chart'!F$3,'2025-Q2'!$F$4:$F$422,'SPDR Chart'!$B11,'2025-Q2'!$D$4:$D$422,"Y") -> 2 | G11: =COUNTIFS('2025-Q2'!$E$4:$E$422,'SPDR Chart'!G$3,'2025-Q2'!$F$4:$F$422,'SPDR Chart'!$B11,'2025-Q2'!$D$4:$D$422,"Y") -> 1 | H11: =COUNTIFS('2025-Q2'!$E$4:$E$422,'SPDR Chart'!H$3,'2025-Q2'!$F$4:$F$422,'SPDR Chart'!$B11,'2025-Q2'!$D$4:$D$422,"Y") -> 1 | I11: =COUNTIFS('2025-Q2'!$E$4:$E$422,'SPDR Chart'!I$3,'2025-Q2'!$F$4:$F$422,'SPDR Chart'!$B11,'2025-Q2'!$D$4:$D$422,"Y") -> 0 | J11: =COUNTIFS('2025-Q2'!$E$4:$E$422,'SPDR Chart'!J$3,'2025-Q2'!$F$4:$F$422,'SPDR Chart'!$B11,'2025-Q2'!$D$4:$D$422,"Y") -> 0 | ... Q11: =COUNTIFS('2025-Q2'!$E$4:$E$422,'SPDR Chart'!Q$3,'2025-Q2'!$F$4:$F$422,'SPDR Chart'!$B11,'2025-Q2'!$D$4:$D$422,"Y") -> 0 | R11: =SUM(C11:Q11) -> 7 | S11: =SUM($R$4:R11)/SUM($R$4:$R$86) -> 0.069364162 | U11: 45763 | V11: =COUNTIFS('2025-Q2'!$E$4:$E$422,'SPDR Chart'!V$3,'2025-Q2'!$F$4:$F$422,'SPDR Chart'!$B11,'2025-Q2'!$D$4:$D$422,"N") -> 0 | W11: =COUNTIFS('2025-Q2'!$E$4:$E$422,'SPDR Chart'!W$3,'2025-Q2'!$F$4:$F$422,'SPDR Chart'!$B11,'2025-Q2'!$D$4:$D$422,"N") -> 0 | X11: =COUNTIFS('2025-Q2'!$E$4:$E$422,'SPDR Chart'!X$3,'2025-Q2'!$F$4:$F$422,'SPDR Chart'!$B11,'2025-Q2'!$D$4:$D$422,"N") -> 0 | Y11: =COUNTIFS('2025-Q2'!$E$4:$E$422,'SPDR Chart'!Y$3,'2025-Q2'!$F$4:$F$422,'SPDR Chart'!$B11,'2025-Q2'!$D$4:$D$422,"N") -> 0 | Z11: =COUNTIFS('2025-Q2'!$E$4:$E$422,'SPDR Chart'!Z$3,'2025-Q2'!$F$4:$F$422,'SPDR Chart'!$B11,'2025-Q2'!$D$4:$D$422,"N") -> 0 | AA11: =COUNTIFS('2025-Q2'!$E$4:$E$422,'SPDR Chart'!AA$3,'2025-Q2'!$F$4:$F$422,'SPDR Chart'!$B11,'2025-Q2'!$D$4:$D$422,"N") -> 0 | AB11: =COUNTIFS('2025-Q2'!$E$4:$E$422,'SPDR Chart'!AB$3,'2025-Q2'!$F$4:$F$422,'SPDR Chart'!$B11,'2025-Q2'!$D$4:$D$422,"N") -> 0 | AC11: =COUNTIFS('2025-Q2'!$E$4:$E$422,'SPDR Chart'!AC$3,'2025-Q2'!$F$4:$F$422,'SPDR Chart'!$B11,'2025-Q2'!$D$4:$D$422,"N") -> 0 | ... AJ11: =COUNTIFS('2025-Q2'!$E$4:$E$422,'SPDR Chart'!AJ$3,'2025-Q2'!$F$4:$F$422,'SPDR Chart'!$B11,'2025-Q2'!$D$4:$D$422,"N") -> 0 | AK11: =SUM(V11:AJ11) -> 0 | AL11: =SUM($AK$4:AK11)/SUM($AK$4:$AK$86) -> 0
B12: 45764 | C12: =COUNTIFS('2025-Q2'!$E$4:$E$422,'SPDR Chart'!C$3,'2025-Q2'!$F$4:$F$422,'SPDR Chart'!$B12,'2025-Q2'!$D$4:$D$422,"Y") -> 0 | D12: =COUNTIFS('2025-Q2'!$E$4:$E$422,'SPDR Chart'!D$3,'2025-Q2'!$F$4:$F$422,'SPDR Chart'!$B12,'2025-Q2'!$D$4:$D$422,"Y") -> 1 | E12: =COUNTIFS('2025-Q2'!$E$4:$E$422,'SPDR Chart'!E$3,'2025-Q2'!$F$4:$F$422,'SPDR Chart'!$B12,'2025-Q2'!$D$4:$D$422,"Y") -> 1 | F12: =COUNTIFS('2025-Q2'!$E$4:$E$422,'SPDR Chart'!F$3,'2025-Q2'!$F$4:$F$422,'SPDR Chart'!$B12,'2025-Q2'!$D$4:$D$422,"Y") -> 9 | G12: =COUNTIFS('2025-Q2'!$E$4:$E$422,'SPDR Chart'!G$3,'2025-Q2'!$F$4:$F$422,'SPDR Chart'!$B12,'2025-Q2'!$D$4:$D$422,"Y") -> 0 | H12: =COUNTIFS('2025-Q2'!$E$4:$E$422,'SPDR Chart'!H$3,'2025-Q2'!$F$4:$F$422,'SPDR Chart'!$B12,'2025-Q2'!$D$4:$D$422,"Y") -> 0 | I12: =COUNTIFS('2025-Q2'!$E$4:$E$422,'SPDR Chart'!I$3,'2025-Q2'!$F$4:$F$422,'SPDR Chart'!$B12,'2025-Q2'!$D$4:$D$422,"Y") -> 0 | J12: =COUNTIFS('2025-Q2'!$E$4:$E$422,'SPDR Chart'!J$3,'2025-Q2'!$F$4:$F$422,'SPDR Chart'!$B12,'2025-Q2'!$D$4:$D$422,"Y") -> 0 | ... Q12: =COUNTIFS('2025-Q2'!$E$4:$E$422,'SPDR Chart'!Q$3,'2025-Q2'!$F$4:$F$422,'SPDR Chart'!$B12,'2025-Q2'!$D$4:$D$422,"Y") -> 0 | R12: =SUM(C12:Q12) -> 13 | S12: =SUM($R$4:R12)/SUM($R$4:$R$86) -> 0.10693642 | U12: 45764 | V12: =COUNTIFS('2025-Q2'!$E$4:$E$422,'SPDR Chart'!V$3,'2025-Q2'!$F$4:$F$422,'SPDR Chart'!$B12,'2025-Q2'!$D$4:$D$422,"N") -> 0 | W12: =COUNTIFS('2025-Q2'!$E$4:$E$422,'SPDR Chart'!W$3,'2025-Q2'!$F$4:$F$422,'SPDR Chart'!$B12,'2025-Q2'!$D$4:$D$422,"N") -> 0 | X12: =COUNTIFS('2025-Q2'!$E$4:$E$422,'SPDR Chart'!X$3,'2025-Q2'!$F$4:$F$422,'SPDR Chart'!$B12,'2025-Q2'!$D$4:$D$422,"N") -> 0 | Y12: =COUNTIFS('2025-Q2'!$E$4:$E$422,'SPDR Chart'!Y$3,'2025-Q2'!$F$4:$F$422,'SPDR Chart'!$B12,'2025-Q2'!$D$4:$D$422,"N") -> 1 | Z12: =COUNTIFS('2025-Q2'!$E$4:$E$422,'SPDR Chart'!Z$3,'2025-Q2'!$F$4:$F$422,'SPDR Chart'!$B12,'2025-Q2'!$D$4:$D$422,"N") -> 0 | AA12: =COUNTIFS('2025-Q2'!$E$4:$E$422,'SPDR Chart'!AA$3,'2025-Q2'!$F$4:$F$422,'SPDR Chart'!$B12,'2025-Q2'!$D$4:$D$422,"N") -> 0 | AB12: =COUNTIFS('2025-Q2'!$E$4:$E$422,'SPDR Chart'!AB$3,'2025-Q2'!$F$4:$F$422,'SPDR Chart'!$B12,'2025-Q2'!$D$4:$D$422,"N") -> 0 | AC12: =COUNTIFS('2025-Q2'!$E$4:$E$422,'SPDR Chart'!AC$3,'2025-Q2'!$F$4:$F$422,'SPDR Chart'!$B12,'2025-Q2'!$D$4:$D$422,"N") -> 0 | ... AJ12: =COUNTIFS('2025-Q2'!$E$4:$E$422,'SPDR Chart'!AJ$3,'2025-Q2'!$F$4:$F$422,'SPDR Chart'!$B12,'2025-Q2'!$D$4:$D$422,"N") -> 0 | AK12: =SUM(V12:AJ12) -> 1 | AL12: =SUM($AK$4:AK12)/SUM($AK$4:$AK$86) -> 0.014925373
B13: 45765 | C13: =COUNTIFS('2025-Q2'!$E$4:$E$422,'SPDR Chart'!C$3,'2025-Q2'!$F$4:$F$422,'SPDR Chart'!$B13,'2025-Q2'!$D$4:$D$422,"Y") -> 0 | D13: =COUNTIFS('2025-Q2'!$E$4:$E$422,'SPDR Chart'!D$3,'2025-Q2'!$F$4:$F$422,'SPDR Chart'!$B13,'2025-Q2'!$D$4:$D$422,"Y") -> 0 | E13: =COUNTIFS('2025-Q2'!$E$4:$E$422,'SPDR Chart'!E$3,'2025-Q2'!$F$4:$F$422,'SPDR Chart'!$B13,'2025-Q2'!$D$4:$D$422,"Y") -> 0 | F13: =COUNTIFS('2025-Q2'!$E$4:$E$422,'SPDR Chart'!F$3,'2025-Q2'!$F$4:$F$422,'SPDR Chart'!$B13,'2025-Q2'!$D$4:$D$422,"Y") -> 0 | G13: =COUNTIFS('2025-Q2'!$E$4:$E$422,'SPDR Chart'!G$3,'2025-Q2'!$F$4:$F$422,'SPDR Chart'!$B13,'2025-Q2'!$D$4:$D$422,"Y") -> 0 | H13: =COUNTIFS('2025-Q2'!$E$4:$E$422,'SPDR Chart'!H$3,'2025-Q2'!$F$4:$F$422,'SPDR Chart'!$B13,'2025-Q2'!$D$4:$D$422,"Y") -> 0 | I13: =COUNTIFS('2025-Q2'!$E$4:$E$422,'SPDR Chart'!I$3,'2025-Q2'!$F$4:$F$422,'SPDR Chart'!$B13,'2025-Q2'!$D$4:$D$422,"Y") -> 0 | J13: =COUNTIFS('2025-Q2'!$E$4:$E$422,'SPDR Chart'!J$3,'2025-Q2'!$F$4:$F$422,'SPDR Chart'!$B13,'2025-Q2'!$D$4:$D$422,"Y") -> 0 | ... Q13: =COUNTIFS('2025-Q2'!$E$4:$E$422,'SPDR Chart'!Q$3,'2025-Q2'!$F$4:$F$422,'SPDR Chart'!$B13,'2025-Q2'!$D$4:$D$422,"Y") -> 0 | R13: =SUM(C13:Q13) -> 0 | S13: =SUM($R$4:R13)/SUM($R$4:$R$86) -> 0.10693642 | U13: 45765 | V13: =COUNTIFS('2025-Q2'!$E$4:$E$422,'SPDR Chart'!V$3,'2025-Q2'!$F$4:$F$422,'SPDR Chart'!$B13,'2025-Q2'!$D$4:$D$422,"N") -> 0 | W13: =COUNTIFS('2025-Q2'!$E$4:$E$422,'SPDR Chart'!W$3,'2025-Q2'!$F$4:$F$422,'SPDR Chart'!$B13,'2025-Q2'!$D$4:$D$422,"N") -> 0 | X13: =COUNTIFS('2025-Q2'!$E$4:$E$422,'SPDR Chart'!X$3,'2025-Q2'!$F$4:$F$422,'SPDR Chart'!$B13,'2025-Q2'!$D$4:$D$422,"N") -> 0 | Y13: =COUNTIFS('2025-Q2'!$E$4:$E$422,'SPDR Chart'!Y$3,'2025-Q2'!$F$4:$F$422,'SPDR Chart'!$B13,'2025-Q2'!$D$4:$D$422,"N") -> 0 | Z13: =COUNTIFS('2025-Q2'!$E$4:$E$422,'SPDR Chart'!Z$3,'2025-Q2'!$F$4:$F$422,'SPDR Chart'!$B13,'2025-Q2'!$D$4:$D$422,"N") -> 0 | AA13: =COUNTIFS('2025-Q2'!$E$4:$E$422,'SPDR Chart'!AA$3,'2025-Q2'!$F$4:$F$422,'SPDR Chart'!$B13,'2025-Q2'!$D$4:$D$422,"N") -> 0 | AB13: =COUNTIFS('2025-Q2'!$E$4:$E$422,'SPDR Chart'!AB$3,'2025-Q2'!$F$4:$F$422,'SPDR Chart'!$B13,'2025-Q2'!$D$4:$D$422,"N") -> 0 | AC13: =COUNTIFS('2025-Q2'!$E$4:$E$422,'SPDR Chart'!AC$3,'2025-Q2'!$F$4:$F$422,'SPDR Chart'!$B13,'2025-Q2'!$D$4:$D$422,"N") -> 0 | ... AJ13: =COUNTIFS('2025-Q2'!$E$4:$E$422,'SPDR Chart'!AJ$3,'2025-Q2'!$F$4:$F$422,'SPDR Chart'!$B13,'2025-Q2'!$D$4:$D$422,"N") -> 0 | AK13: =SUM(V13:AJ13) -> 0 | AL13: =SUM($AK$4:AK13)/SUM($AK$4:$AK$86) -> 0.014925373
B14: 45766 | C14: =COUNTIFS('2025-Q2'!$E$4:$E$422,'SPDR Chart'!C$3,'2025-Q2'!$F$4:$F$422,'SPDR Chart'!$B14,'2025-Q2'!$D$4:$D$422,"Y") -> 0 | D14: =COUNTIFS('2025-Q2'!$E$4:$E$422,'SPDR Chart'!D$3,'2025-Q2'!$F$4:$F$422,'SPDR Chart'!$B14,'2025-Q2'!$D$4:$D$422,"Y") -> 0 | E14: =COUNTIFS('2025-Q2'!$E$4:$E$422,'SPDR Chart'!E$3,'2025-Q2'!$F$4:$F$422,'SPDR Chart'!$B14,'2025-Q2'!$D$4:$D$422,"Y") -> 0 | F14: =COUNTIFS('2025-Q2'!$E$4:$E$422,'SPDR Chart'!F$3,'2025-Q2'!$F$4:$F$422,'SPDR Chart'!$B14,'2025-Q2'!$D$4:$D$422,"Y") -> 0 | G14: =COUNTIFS('2025-Q2'!$E$4:$E$422,'SPDR Chart'!G$3,'2025-Q2'!$F$4:$F$422,'SPDR Chart'!$B14,'2025-Q2'!$D$4:$D$422,"Y") -> 0 | H14: =COUNTIFS('2025-Q2'!$E$4:$E$422,'SPDR Chart'!H$3,'2025-Q2'!$F$4:$F$422,'SPDR Chart'!$B14,'2025-Q2'!$D$4:$D$422,"Y") -> 0 | I14: =COUNTIFS('2025-Q2'!$E$4:$E$422,'SPDR Chart'!I$3,'2025-Q2'!$F$4:$F$422,'SPDR Chart'!$B14,'2025-Q2'!$D$4:$D$422,"Y") -> 0 | J14: =COUNTIFS('2025-Q2'!$E$4:$E$422,'SPDR Chart'!J$3,'2025-Q2'!$F$4:$F$422,'SPDR Chart'!$B14,'2025-Q2'!$D$4:$D$422,"Y") -> 0 | ... Q14: =COUNTIFS('2025-Q2'!$E$4:$E$422,'SPDR Chart'!Q$3,'2025-Q2'!$F$4:$F$422,'SPDR Chart'!$B14,'2025-Q2'!$D$4:$D$422,"Y") -> 0 | R14: =SUM(C14:Q14) -> 0 | S14: =SUM($R$4:R14)/SUM($R$4:$R$86) -> 0.10693642 | U14: 45766 | V14: =COUNTIFS('2025-Q2'!$E$4:$E$422,'SPDR Chart'!V$3,'2025-Q2'!$F$4:$F$422,'SPDR Chart'!$B14,'2025-Q2'!$D$4:$D$422,"N") -> 0 | W14: =COUNTIFS('2025-Q2'!$E$4:$E$422,'SPDR Chart'!W$3,'2025-Q2'!$F$4:$F$422,'SPDR Chart'!$B14,'2025-Q2'!$D$4:$D$422,"N") -> 0 | X14: =COUNTIFS('2025-Q2'!$E$4:$E$422,'SPDR Chart'!X$3,'2025-Q2'!$F$4:$F$422,'SPDR Chart'!$B14,'2025-Q2'!$D$4:$D$422,"N") -> 0 | Y14: =COUNTIFS('2025-Q2'!$E$4:$E$422,'SPDR Chart'!Y$3,'2025-Q2'!$F$4:$F$422,'SPDR Chart'!$B14,'2025-Q2'!$D$4:$D$422,"N") -> 0 | Z14: =COUNTIFS('2025-Q2'!$E$4:$E$422,'SPDR Chart'!Z$3,'2025-Q2'!$F$4:$F$422,'SPDR Chart'!$B14,'2025-Q2'!$D$4:$D$422,"N") -> 0 | AA14: =COUNTIFS('2025-Q2'!$E$4:$E$422,'SPDR Chart'!AA$3,'2025-Q2'!$F$4:$F$422,'SPDR Chart'!$B14,'2025-Q2'!$D$4:$D$422,"N") -> 0 | AB14: =COUNTIFS('2025-Q2'!$E$4:$E$422,'SPDR Chart'!AB$3,'2025-Q2'!$F$4:$F$422,'SPDR Chart'!$B14,'2025-Q2'!$D$4:$D$422,"N") -> 0 | AC14: =COUNTIFS('2025-Q2'!$E$4:$E$422,'SPDR Chart'!AC$3,'2025-Q2'!$F$4:$F$422,'SPDR Chart'!$B14,'2025-Q2'!$D$4:$D$422,"N") -> 0 | ... AJ14: =COUNTIFS('2025-Q2'!$E$4:$E$422,'SPDR Chart'!AJ$3,'2025-Q2'!$F$4:$F$422,'SPDR Chart'!$B14,'2025-Q2'!$D$4:$D$422,"N") -> 0 | AK14: =SUM(V14:AJ14) -> 0 | AL14: =SUM($AK$4:AK14)/SUM($AK$4:$AK$86) -> 0.014925373
B15: 45767 | C15: =COUNTIFS('2025-Q2'!$E$4:$E$422,'SPDR Chart'!C$3,'2025-Q2'!$F$4:$F$422,'SPDR Chart'!$B15,'2025-Q2'!$D$4:$D$422,"Y") -> 0 | D15: =COUNTIFS('2025-Q2'!$E$4:$E$422,'SPDR Chart'!D$3,'2025-Q2'!$F$4:$F$422,'SPDR Chart'!$B15,'2025-Q2'!$D$4:$D$422,"Y") -> 0 | E15: =COUNTIFS('2025-Q2'!$E$4:$E$422,'SPDR Chart'!E$3,'2025-Q2'!$F$4:$F$422,'SPDR Chart'!$B15,'2025-Q2'!$D$4:$D$422,"Y") -> 0 | F15: =COUNTIFS('2025-Q2'!$E$4:$E$422,'SPDR Chart'!F$3,'2025-Q2'!$F$4:$F$422,'SPDR Chart'!$B15,'2025-Q2'!$D$4:$D$422,"Y") -> 0 | G15: =COUNTIFS('2025-Q2'!$E$4:$E$422,'SPDR Chart'!G$3,'2025-Q2'!$F$4:$F$422,'SPDR Chart'!$B15,'2025-Q2'!$D$4:$D$422,"Y") -> 0 | H15: =COUNTIFS('2025-Q2'!$E$4:$E$422,'SPDR Chart'!H$3,'2025-Q2'!$F$4:$F$422,'SPDR Chart'!$B15,'2025-Q2'!$D$4:$D$422,"Y") -> 0 | I15: =COUNTIFS('2025-Q2'!$E$4:$E$422,'SPDR Chart'!I$3,'2025-Q2'!$F$4:$F$422,'SPDR Chart'!$B15,'2025-Q2'!$D$4:$D$422,"Y") -> 0 | J15: =COUNTIFS('2025-Q2'!$E$4:$E$422,'SPDR Chart'!J$3,'2025-Q2'!$F$4:$F$422,'SPDR Chart'!$B15,'2025-Q2'!$D$4:$D$422,"Y") -> 0 | ... Q15: =COUNTIFS('2025-Q2'!$E$4:$E$422,'SPDR Chart'!Q$3,'2025-Q2'!$F$4:$F$422,'SPDR Chart'!$B15,'2025-Q2'!$D$4:$D$422,"Y") -> 0 | R15: =SUM(C15:Q15) -> 0 | S15: =SUM($R$4:R15)/SUM($R$4:$R$86) -> 0.10693642 | U15: 45767 | V15: =COUNTIFS('2025-Q2'!$E$4:$E$422,'SPDR Chart'!V$3,'2025-Q2'!$F$4:$F$422,'SPDR Chart'!$B15,'2025-Q2'!$D$4:$D$422,"N") -> 0 | W15: =COUNTIFS('2025-Q2'!$E$4:$E$422,'SPDR Chart'!W$3,'2025-Q2'!$F$4:$F$422,'SPDR Chart'!$B15,'2025-Q2'!$D$4:$D$422,"N") -> 0 | X15: =COUNTIFS('2025-Q2'!$E$4:$E$422,'SPDR Chart'!X$3,'2025-Q2'!$F$4:$F$422,'SPDR Chart'!$B15,'2025-Q2'!$D$4:$D$422,"N") -> 0 | Y15: =COUNTIFS('2025-Q2'!$E$4:$E$422,'SPDR Chart'!Y$3,'2025-Q2'!$F$4:$F$422,'SPDR Chart'!$B15,'2025-Q2'!$D$4:$D$422,"N") -> 0 | Z15: =COUNTIFS('2025-Q2'!$E$4:$E$422,'SPDR Chart'!Z$3,'2025-Q2'!$F$4:$F$422,'SPDR Chart'!$B15,'2025-Q2'!$D$4:$D$422,"N") -> 0 | AA15: =COUNTIFS('2025-Q2'!$E$4:$E$422,'SPDR Chart'!AA$3,'2025-Q2'!$F$4:$F$422,'SPDR Chart'!$B15,'2025-Q2'!$D$4:$D$422,"N") -> 0 | AB15: =COUNTIFS('2025-Q2'!$E$4:$E$422,'SPDR Chart'!AB$3,'2025-Q2'!$F$4:$F$422,'SPDR Chart'!$B15,'2025-Q2'!$D$4:$D$422,"N") -> 0 | AC15: =COUNTIFS('2025-Q2'!$E$4:$E$422,'SPDR Chart'!AC$3,'2025-Q2'!$F$4:$F$422,'SPDR Chart'!$B15,'2025-Q2'!$D$4:$D$422,"N") -> 0 | ... AJ15: =COUNTIFS('2025-Q2'!$E$4:$E$422,'SPDR Chart'!AJ$3,'2025-Q2'!$F$4:$F$422,'SPDR Chart'!$B15,'2025-Q2'!$D$4:$D$422,"N") -> 0 | AK15: =SUM(V15:AJ15) -> 0 | AL15: =SUM($AK$4:AK15)/SUM($AK$4:$AK$86) -> 0.014925373
... B86: 45838 | C86: =COUNTIFS('2025-Q2'!$E$4:$E$422,'SPDR Chart'!C$3,'2025-Q2'!$F$4:$F$422,'SPDR Chart'!$B86,'2025-Q2'!$D$4:$D$422,"Y") -> 0 | D86: =COUNTIFS('2025-Q2'!$E$4:$E$422,'SPDR Chart'!D$3,'2025-Q2'!$F$4:$F$422,'SPDR Chart'!$B86,'2025-Q2'!$D$4:$D$422,"Y") -> 0 | E86: =COUNTIFS('2025-Q2'!$E$4:$E$422,'SPDR Chart'!E$3,'2025-Q2'!$F$4:$F$422,'SPDR Chart'!$B86,'2025-Q2'!$D$4:$D$422,"Y") -> 0 | F86: =COUNTIFS('2025-Q2'!$E$4:$E$422,'SPDR Chart'!F$3,'2025-Q2'!$F$4:$F$422,'SPDR Chart'!$B86,'2025-Q2'!$D$4:$D$422,"Y") -> 0 | G86: =COUNTIFS('2025-Q2'!$E$4:$E$422,'SPDR Chart'!G$3,'2025-Q2'!$F$4:$F$422,'SPDR Chart'!$B86,'2025-Q2'!$D$4:$D$422,"Y") -> 0 | H86: =COUNTIFS('2025-Q2'!$E$4:$E$422,'SPDR Chart'!H$3,'2025-Q2'!$F$4:$F$422,'SPDR Chart'!$B86,'2025-Q2'!$D$4:$D$422,"Y") -> 0 | I86: =COUNTIFS('2025-Q2'!$E$4:$E$422,'SPDR Chart'!I$3,'2025-Q2'!$F$4:$F$422,'SPDR Chart'!$B86,'2025-Q2'!$D$4:$D$422,"Y") -> 0 | J86: =COUNTIFS('2025-Q2'!$E$4:$E$422,'SPDR Chart'!J$3,'2025-Q2'!$F$4:$F$422,'SPDR Chart'!$B86,'2025-Q2'!$D$4:$D$422,"Y") -> 0 | ... Q86: =COUNTIFS('2025-Q2'!$E$4:$E$422,'SPDR Chart'!Q$3,'2025-Q2'!$F$4:$F$422,'SPDR Chart'!$B86,'2025-Q2'!$D$4:$D$422,"Y") -> 0 | R86: =SUM(C86:Q86) -> 0 | S86: =SUM($R$4:R86)/SUM($R$4:$R$86) -> 1 | U86: 45838 | V86: =COUNTIFS('2025-Q2'!$E$4:$E$422,'SPDR Chart'!V$3,'2025-Q2'!$F$4:$F$422,'SPDR Chart'!$B86,'2025-Q2'!$D$4:$D$422,"N") -> 0 | W86: =COUNTIFS('2025-Q2'!$E$4:$E$422,'SPDR Chart'!W$3,'2025-Q2'!$F$4:$F$422,'SPDR Chart'!$B86,'2025-Q2'!$D$4:$D$422,"N") -> 0 | X86: =COUNTIFS('2025-Q2'!$E$4:$E$422,'SPDR Chart'!X$3,'2025-Q2'!$F$4:$F$422,'SPDR Chart'!$B86,'2025-Q2'!$D$4:$D$422,"N") -> 0 | Y86: =COUNTIFS('2025-Q2'!$E$4:$E$422,'SPDR Chart'!Y$3,'2025-Q2'!$F$4:$F$422,'SPDR Chart'!$B86,'2025-Q2'!$D$4:$D$422,"N") -> 0 | Z86: =COUNTIFS('2025-Q2'!$E$4:$E$422,'SPDR Chart'!Z$3,'2025-Q2'!$F$4:$F$422,'SPDR Chart'!$B86,'2025-Q2'!$D$4:$D$422,"N") -> 0 | AA86: =COUNTIFS('2025-Q2'!$E$4:$E$422,'SPDR Chart'!AA$3,'2025-Q2'!$F$4:$F$422,'SPDR Chart'!$B86,'2025-Q2'!$D$4:$D$422,"N") -> 0 | AB86: =COUNTIFS('2025-Q2'!$E$4:$E$422,'SPDR Chart'!AB$3,'2025-Q2'!$F$4:$F$422,'SPDR Chart'!$B86,'2025-Q2'!$D$4:$D$422,"N") -> 0 | AC86: =COUNTIFS('2025-Q2'!$E$4:$E$422,'SPDR Chart'!AC$3,'2025-Q2'!$F$4:$F$422,'SPDR Chart'!$B86,'2025-Q2'!$D$4:$D$422,"N") -> 0 | ... AJ86: =COUNTIFS('2025-Q2'!$E$4:$E$422,'SPDR Chart'!AJ$3,'2025-Q2'!$F$4:$F$422,'SPDR Chart'!$B86,'2025-Q2'!$D$4:$D$422,"N") -> 0 | AK86: =SUM(V86:AJ86) -> 0 | AL86: =SUM($AK$4:AK86)/SUM($AK$4:$AK$86) -> 1

Sheet Summary Data
B1: % in SPY | C1: Total | D1: # in Up | E1: % in Up | F1: # in Dwn | G1: % in Dwn | H1: # in SW | I1: % in SW
B2: =COUNTIF('2025-Q2'!$D$4:$D$422,"Y")/C2 -> 0.82816229 | C2: =COUNTA('2025-Q2'!$D$4:$D$422) -> 419 | D2: =COUNTIF('2025-Q2'!$S$4:$S$422,"Up") -> 51 | E2: =D2/$C$2 -> 0.12171838 | F2: =COUNTIF('2025-Q2'!$S$4:$S$422,"Dwn") -> 166 | G2: =F2/$C$2 -> 0.39618138 | H2: =COUNTIF('2025-Q2'!$S$4:$S$422,"Sw") -> 202 | I2: =H2/$C$2 -> 0.48210024
D3: Up: R | F3: Down: R | H3: SW: R | J3: All: R
D4: =SUM('2025-Q2'!$CC$4:$CC$422) -> -8.3953557 | F4: =SUM('2025-Q2'!$CE$4:$CE$422) -> 10.963955 | H4: =SUM('2025-Q2'!$CG$4:$CG$422) -> 9.9627467 | J4: =D4+F4+H4 -> 12.531346
B8: Risk Units | C8: Expectancy
A9: Up | B9: =D4 -> -8.3953557 | C9: =Expectancy!Q3 -> -0.16461482
A10: Down | B10: =F4 -> 10.963955 | C10: =Expectancy!R3 -> 0.066047922
A11: SW | B11: =H4 -> 9.9627467 | C11: =Expectancy!S3 -> 0.049320528

Sheet Summary
A1: 2025 -- Q1
A3: Executive Summary:
A4: =_xlfn.CONCAT(" For the ",A1," earnings season, ", TEXT('Stats Roll Up'!R4,"###")& " earnings trades were taken, ",TEXT('Summary Data'!B2,"00%")," were stocks from the S&P 500.") -> For the 2025 -- Q1 earnings season, 413 earnings trades were taken, 83% were stocks from the S&P 500.
A5: ● | B5: =CONCATENATE("Overall, the three pillars of the strategy producted: ") -> Overall, the three pillars of the strategy producted: | O5: =TEXT('Summary Data'!J$4,"0") -> 13 | Q5: risk units.
A6: Up Trending Stocks:
A7: ● | B7: =_xlfn.CONCAT('Summary Data'!$D$2," of the trades were stocks in an up trend."," This is ", TEXT('Summary Data'!$E$2,"##%")," of all trades.") -> 51 of the trades were stocks in an up trend. This is 12% of all trades.
A8: ● | B8: =_xlfn.CONCAT(TEXT('Stats Roll Up'!$G$4,"00.0%")," of the up trendng stocks opened higher after earnings. The average gap higher was ",TEXT('Stats Roll Up'!$D$4,"0.0%"),".") -> 47.1% of the up trendng stocks opened higher after earnings. The average gap higher was 4.6%.
A9: ● | B9: =_xlfn.CONCAT(TEXT('Stats Roll Up'!$AC$4,"00.0%")," of the up trendng stocks opened lower after earnings. The average gap down from an up trend was ",TEXT('Stats Roll Up'!$AE$4,"0.0%"),".") -> 52.9% of the up trendng stocks opened lower after earnings. The average gap down from an up trend was 5.2%.
A10: ● | B10: =CONCATENATE("For up trends, the strategy produced: ") -> For up trends, the strategy produced: | M10: ='Summary Data'!$D$4 -> -8.3953557 | N10: risk units.
A11: ● | B11: Up trends had an expectancy of: | K11: =Expectancy!$Q$3 -> -0.16461482 | M11: risk units per trade.
A13: Down Trending Stocks:
A14: ● | B14: =_xlfn.CONCAT('Summary Data'!$F$2," of the trades were stocks in an down trend."," This is ", TEXT('Summary Data'!$G$2,"##%")," of all trades.") -> 166 of the trades were stocks in an down trend. This is 40% of all trades.
A15: ● | B15: =_xlfn.CONCAT(TEXT('Stats Roll Up'!$Y$4,"00.0%")," of the down trendng stocks opened lower after earnings. The average gap down was ",TEXT('Stats Roll Up'!$AA$4,"0.0%"),".") -> 55.4% of the down trendng stocks opened lower after earnings. The average gap down was 4.1%.
A16: ● | B16: =_xlfn.CONCAT(TEXT('Stats Roll Up'!$K$4,"00.0%")," of the down trendng stocks opened higher after earnings. The average gap up from a down trend was ",TEXT('Stats Roll Up'!$M$4,"0.0%"),".") -> 44.6% of the down trendng stocks opened higher after earnings. The average gap up from a down trend was 4.3%.
A17: ● | B17: =CONCATENATE("For down trends, the strategy produced: ") -> For down trends, the strategy produced: | N17: ='Summary Data'!$F$4 -> 10.963955 | O17: =_xlfn.CONCAT("risk units.") -> risk units.
A18: ● | B18: Down trends had an expectancy of: | L18: =Expectancy!$R$3 -> 0.066047922 | N18: risk units per trade.
A20: Sideways Trending Stocks:
A21: ● | B21: =_xlfn.CONCAT('Summary Data'!$H$2," of the trades were stocks in a sideways trend."," This is ", TEXT('Summary Data'!$I$2,"00%")," of all trades.") -> 202 of the trades were stocks in a sideways trend. This is 48% of all trades.
A22: ● | B22: =_xlfn.CONCAT(TEXT('Stats Roll Up'!$O$4,"00.0%")," of the sideways stocks opened higher after earnings. The average gap up was ",TEXT('Stats Roll Up'!$Q$4,"0.0%"),".") -> 50.5% of the sideways stocks opened higher after earnings. The average gap up was 5.1%.
A23: ● | B23: =_xlfn.CONCAT(TEXT('Stats Roll Up'!$AG$4,"00.0%")," of the sideways stocks opened lower after earnings. The average gap down from a sideways trend was ",TEXT('Stats Roll Up'!$AI$4,"0.0%"),".") -> 48.5% of the sideways stocks opened lower after earnings. The average gap down from a sideways trend was 4.7%.
A24: ● | B24: =CONCATENATE("For sideways trends, the strategy produced: ") -> For sideways trends, the strategy produced: | N24: ='Summary Data'!$H$4 -> 9.9627467 | O24: =_xlfn.CONCAT("risk units.") -> risk units.
A25: ● | B25: Sideways trends had an expectancy of: | M25: =Expectancy!$S$3 -> 0.049320528 | O25: risk units per trade.
A44: 2025 -- Q1
A46: Sector Performance:
A47: Up Trending Stocks, Risk Units by Sector:
A61: Down Trending Stocks, Risk Units by Sector:
A75: Sideways Trending Stocks:
A89: 2025 -- Q2
A91: Sector Performance, continued:
A92: Total Risk Units by Sector, w/ Expectancy:

Sheet Earnings
A1: Date/Time | B1: Ticker | C1: When | D1: Index
A2: 45778.024 | B2: BVN | C2: on 5/1/25, 2:35 AM Before Market Eastern Standard Time | D2: =_xlfn.XLOOKUP(B2,Indices!$A$2:$A$2676,Indices!$B$2:$B$2676,"")
A3: 45778.167 | B3: WCC | C3: on 5/1/25, 6:00 AM Before Market Eastern Standard Time | D3: =_xlfn.XLOOKUP(B3,Indices!$A$2:$A$2676,Indices!$B$2:$B$2676,"") -> S&P Mid
A4: 45778.167 | B4: LXP | C4: on 5/1/25, 6:00 AM Before Market Eastern Standard Time | D4: =_xlfn.XLOOKUP(B4,Indices!$A$2:$A$2676,Indices!$B$2:$B$2676,"") -> IWM
A5: 45778.167 | B5: APD | C5: on 5/1/25, 6:00 AM Before Market Eastern Standard Time | D5: =_xlfn.XLOOKUP(B5,Indices!$A$2:$A$2676,Indices!$B$2:$B$2676,"") -> SP500
A6: 45778.167 | B6: ECVT | C6: on 5/1/25, 6:00 AM Before Market Eastern Standard Time | D6: =_xlfn.XLOOKUP(B6,Indices!$A$2:$A$2676,Indices!$B$2:$B$2676,"") -> IWM
A7: 45778.167 | B7: TRGP | C7: on 5/1/25, 6:00 AM Before Market Eastern Standard Time | D7: =_xlfn.XLOOKUP(B7,Indices!$A$2:$A$2676,Indices!$B$2:$B$2676,"") -> SP500
A8: 45778.167 | B8: OCSL | C8: on 5/1/25, 6:00 AM Before Market Eastern Standard Time | D8: =_xlfn.XLOOKUP(B8,Indices!$A$2:$A$2676,Indices!$B$2:$B$2676,"")
A9: 45778.167 | B9: WD | C9: on 5/1/25, 6:00 AM Before Market Eastern Standard Time | D9: =_xlfn.XLOOKUP(B9,Indices!$A$2:$A$2676,Indices!$B$2:$B$2676,"") -> IWM
A10: 45778.167 | B10: EL | C10: on 5/1/25, 6:00 AM Before Market Eastern Standard Time | D10: =_xlfn.XLOOKUP(B10,Indices!$A$2:$A$2676,Indices!$B$2:$B$2676,"") -> SP500
A11: 45778.167 | B11: CCO | C11: on 5/1/25, 6:00 AM Before Market Eastern Standard Time | D11: =_xlfn.XLOOKUP(B11,Indices!$A$2:$A$2676,Indices!$B$2:$B$2676,"") -> IWM
A12: 45778.167 | B12: XFOR | C12: on 5/1/25, 6:01 AM Before Market Eastern Standard Time | D12: =_xlfn.XLOOKUP(B12,Indices!$A$2:$A$2676,Indices!$B$2:$B$2676,"")
A13: 45778.188 | B13: AGIO | C13: on 5/1/25, 6:30 AM Before Market Eastern Standard Time | D13: =_xlfn.XLOOKUP(B13,Indices!$A$2:$A$2676,Indices!$B$2:$B$2676,"") -> IWM
... A440: 45782.59 | B440: GBDC | C440: on 5/5/25, 4:10 PM After Market Eastern Standard Time | D440: =_xlfn.XLOOKUP(B440,Indices!$A$2:$A$2676,Indices!$B$2:$B$2676,"")
A441: 45782.592 | B441: TRUE | C441: on 5/5/25, 4:13 PM After Market Eastern Standard Time | D441: =_xlfn.XLOOKUP(B441,Indices!$A$2:$A$2676,Indices!$B$2:$B$2676,"")
A442: 45782.594 | B442: MYPS | C442: on 5/5/25, 4:15 PM After Market Eastern Standard Time | D442: =_xlfn.XLOOKUP(B442,Indices!$A$2:$A$2676,Indices!$B$2:$B$2676,"")
A443: 45782.594 | B443: WMB | C443: on 5/5/25, 4:15 PM After Market Eastern Standard Time | D443: =_xlfn.XLOOKUP(B443,Indices!$A$2:$A$2676,Indices!$B$2:$B$2676,"") -> SP500
A444: 45782.594 | B444: AESI | C444: on 5/5/25, 4:15 PM After Market Eastern Standard Time | D444: =_xlfn.XLOOKUP(B444,Indices!$A$2:$A$2676,Indices!$B$2:$B$2676,"") -> IWM
A445: 45782.594 | B445: SPNT | C445: on 5/5/25, 4:15 PM After Market Eastern Standard Time | D445: =_xlfn.XLOOKUP(B445,Indices!$A$2:$A$2676,Indices!$B$2:$B$2676,"") -> IWM
A446: 45782.594 | B446: GECC | C446: on 5/5/25, 4:15 PM After Market Eastern Standard Time | D446: =_xlfn.XLOOKUP(B446,Indices!$A$2:$A$2676,Indices!$B$2:$B$2676,"")
A447: 45782.594 | B447: ACEL | C447: on 5/5/25, 4:15 PM After Market Eastern Standard Time | D447: =_xlfn.XLOOKUP(B447,Indices!$A$2:$A$2676,Indices!$B$2:$B$2676,"") -> IWM
A448: 45782.594 | B448: ANAB | C448: on 5/5/25, 4:15 PM After Market Eastern Standard Time | D448: =_xlfn.XLOOKUP(B448,Indices!$A$2:$A$2676,Indices!$B$2:$B$2676,"") -> IWM
A449: 45782.594 | B449: IPAR | C449: on 5/5/25, 4:15 PM After Market Eastern Standard Time | D449: =_xlfn.XLOOKUP(B449,Indices!$A$2:$A$2676,Indices!$B$2:$B$2676,"") -> IWM
A450: 45782.594 | B450: CRD/B | C450: on 5/5/25, 4:15 PM After Market Eastern Standard Time | D450: =_xlfn.XLOOKUP(B450,Indices!$A$2:$A$2676,Indices!$B$2:$B$2676,"")
A451: 45782.594 | B451: LTC | C451: on 5/5/25, 4:15 PM After Market Eastern Standard Time | D451: =_xlfn.XLOOKUP(B451,Indices!$A$2:$A$2676,Indices!$B$2:$B$2676,"") -> IWM
A452: 45782.594 | B452: NGVT | C452: on 5/5/25, 4:15 PM After Market Eastern Standard Time | D452: =_xlfn.XLOOKUP(B452,Indices!$A$2:$A$2676,Indices!$B$2:$B$2676,"") -> IWM
A453: 45782.594 | B453: CRBG | C453: on 5/5/25, 4:15 PM After Market Eastern Standard Time | D453: =_xlfn.XLOOKUP(B453,Indices!$A$2:$A$2676,Indices!$B$2:$B$2676,"")
... A3326: 45838.625 | B3326: ELTP | C3326: on 6/30/25 After Market Eastern Standard Time | D3326: =_xlfn.XLOOKUP(B3326,Indices!$A$2:$A$2676,Indices!$B$2:$B$2676,"")
D3327: =_xlfn.XLOOKUP(B3327,Indices!$A$2:$A$2676,Indices!$B$2:$B$2676,"")
D3328: =_xlfn.XLOOKUP(B3328,Indices!$A$2:$A$2676,Indices!$B$2:$B$2676,"")
D3329: =_xlfn.XLOOKUP(B3329,Indices!$A$2:$A$2676,Indices!$B$2:$B$2676,"")
D3330: =_xlfn.XLOOKUP(B3330,Indices!$A$2:$A$2676,Indices!$B$2:$B$2676,"")
D3331: =_xlfn.XLOOKUP(B3331,Indices!$A$2:$A$2676,Indices!$B$2:$B$2676,"")
D3332: =_xlfn.XLOOKUP(B3332,Indices!$A$2:$A$2676,Indices!$B$2:$B$2676,"")
D3333: =_xlfn.XLOOKUP(B3333,Indices!$A$2:$A$2676,Indices!$B$2:$B$2676,"")
D3334: =_xlfn.XLOOKUP(B3334,Indices!$A$2:$A$2676,Indices!$B$2:$B$2676,"")
D3335: =_xlfn.XLOOKUP(B3335,Indices!$A$2:$A$2676,Indices!$B$2:$B$2676,"")
D3336: =_xlfn.XLOOKUP(B3336,Indices!$A$2:$A$2676,Indices!$B$2:$B$2676,"")
D3337: =_xlfn.XLOOKUP(B3337,Indices!$A$2:$A$2676,Indices!$B$2:$B$2676,"")
D3338: =_xlfn.XLOOKUP(B3338,Indices!$A$2:$A$2676,Indices!$B$2:$B$2676,"")
...

Sheet 2025-Q2
A1: Formulas --> | B1: {=IFERROR(_xlfn.XLOOKUP(A4,Earnings!$B$2:$B$9984,LEFT(Earnings!$C$2:$C$9984,37)),"Can't Find Date***")} -> Can't Find Date*** | E1: =_xlfn.XLOOKUP(A1,[1]SP500!$A$2:$A$655,[1]SP500!$B$2:$B$655) -> #N/A | F1: =IFERROR(TRIM(MID(B1,FIND("/",B1,1)-2,8)),"") | I1: ------------ Gap Data ------------ | N1: ------- Strategy P&L ------- | S1: --- Trend Data --- | U1: ---------- Entry ---------- | Y1: Exit at Open, or Other Exit | AA1: Mkt at Open, or, Other Exit | AB1: -------- Market on Close Stats -------- | AH1: ---------- Actual P&L ---------- | AO1: Market on Close Comparison Data | BC1: Key Strategy Flags | BK1: Expectancy Update with row del | BO1: ---- % Gapping Up ----- | BW1: Hide These these columns track the strategies three pillars per trade and cumulatively | CC1: Hide These these columns track the strategies three pillars per trade and cumulatively | CI1: Hide These (Sector 3 Pillars) these columns track the strategies three pillars per trade and cumulatively | CP1: Hide These (Sector 3 Pillars) these columns track the strategies three pillars per trade and cumulatively | CW1: Hide These (Sector 3 Pillars) these columns track the strategies three pillars per trade and cumulatively | DD1: Hide These (Sector 3 Pillars) these columns track the strategies three pillars per trade and cumulatively | DK1: Hide These (Sector 3 Pillars) these columns track the strategies three pillars per trade and cumulatively | DR1: Hide These (Sector 3 Pillars) these columns track the strategies three pillars per trade and cumulatively | DY1: Hide These (Sector 3 Pillars) these columns track the strategies three pillars per trade and cumulatively | EF1: Hide These (Sector 3 Pillars) these columns track the strategies three pillars per trade and cumulatively | EM1: Hide These (Sector 3 Pillars) these columns track the strategies three pillars per trade and cumulatively | ET1: Hide These (Sector 3 Pillars) these columns track the strategies three pillars per trade and cumulatively | FA1: Hide These (Sector 3 Pillars) these columns track the strategies three pillars per trade and cumulatively | FH1: Hide These (Sector 3 Pillars) these columns track the strategies three pillars per trade and cumulatively | FO1: Hide These (Sector 3 Pillars) these columns track the strategies three pillars per trade and cumulatively | FV1: Hide These (Sector 3 Pillars) these columns track the strategies three pillars per trade and cumulatively | GC1: Hide These (Sector 3 Pillars) these columns track the strategies three pillars per trade and cumulatively | GJ1: Hide These (Sector 3 Pillars) these columns track the strategies three pillars per trade and cumulatively
A2: Cheat -> | B2: hide | C2: hide | E2: ● | F2: ● | G2: ● | H2: ● | I2: ↓ | J2: ↓ | K2: ● | L2: ● | M2: ● | N2: ● | O2: ● | P2: ● | Q2: ● | R2: ● | S2: ● | T2: ↓ | U2: ● | V2: ↓ | W2: ↓ | X2: ● | Y2: ● | Z2: ↓ | AA2: ● | AB2: ● | AC2: ↓ | AD2: ● | AE2: ● | AF2: ● | AG2: ● | AH2: ↓ | AI2: ● | AJ2: ● | AK2: ● | AL2: ● | AO2: Risk Units | AU2: P & L | BC2: =SUM(BC4:BC422) -> 24 | BD2: =SUM(BD4:BD422) -> 74 | BE2: =SUM(BE4:BE422) -> 102 | BF2: =(BC2+BE2+BG2)/(BC2+BE2+BG2+BD2+BH2+BI2) -> 0.52278177 | BG2: =SUM(BG4:BG422) -> 92 | BH2: =SUM(BH4:BH422) -> 27 | BI2: =SUM(BI4:BI422) -> 98 | BO2: form | BP2: form | BQ2: form | BR2: form | BS2: form | BT2: form | BU2: form | BV2: form | BW2: form | BX2: form | BY2: form | BZ2: form | CA2: form | CB2: form | CC2: form | CD2: form | CE2: form | CF2: form | CG2: form | CH2: form | CI2: XLK | CJ2: form | CK2: form | CL2: form | CM2: form | CN2: form | CO2: form | CP2: IGV | CQ2: form | CR2: form | CS2: form | CT2: form | CU2: form | CV2: form | CW2: XLY | CX2: form | CY2: form | CZ2: form | DA2: form | DB2: form | DC2: form | DD2: XLP | DE2: form | DF2: form | DG2: form | DH2: form | DI2: form | DJ2: form | DK2: XLC | DL2: form | DM2: form | DN2: form | DO2: form | DP2: form | DQ2: form | DR2: XLF | DS2: form | DT2: form | DU2: form | DV2: form | DW2: form | DX2: form | DY2: XLI | DZ2: form | EA2: form | EB2: form | EC2: form | ED2: form | EE2: form | EF2: XLV | EG2: form | EH2: form | EI2: form | EJ2: form | EK2: form | EL2: form | EM2: XLB | EN2: form | EO2: form | EP2: form | EQ2: form | ER2: form | ES2: form | ET2: SMH | EU2: form | EV2: form | EW2: form | EX2: form | EY2: form | EZ2: form | FA2: XLE | FB2: form | FC2: form | FD2: form | FE2: form | FF2: form | FG2: form | FH2: XLU | FI2: form | FJ2: form | FK2: form | FL2: form | FM2: form | FN2: form | FO2: XLRE | FP2: form | FQ2: form | FR2: form | FS2: form | FT2: form | FU2: form | FV2: INS | FW2: form | FX2: form | FY2: form | FZ2: form | GA2: form | GB2: form | GC2: H-INS | GD2: form | GE2: form | GF2: form | GG2: form | GH2: form | GI2: form | GJ2: XHB | GK2: form | GL2: form | GM2: form | GN2: form | GO2: form | GP2: form | GS2: SPY | GT2: SPY | GU2: SPY | GV2: SPY | GW2: SPY | GX2: SPY | GY2: SPY | GZ2: SPY | HA2: Not Spy | HB2: Not Spy | HC2: Not Spy | HD2: Not Spy | HE2: Not Spy | HF2: Not Spy | HG2: Not Spy | HH2: Not Spy | HI2: Gap ↓ from Dwn Tr | HK2: Gap ↑ from Dwn Tr | HM2: Gap ↑ from Up Tr | HO2: Gap ↓ from Up Tr | HQ2: Gap ↑ from Sw Tr | HS2: Gap ↓ from Sw Tr | HU2: hide | HV2: hide
A3: Stock | B3: Earnings Date | C3: TrCh | D3: In SPY? | E3: Sector | F3: Date | G3: AMO, BMO | H3: S/O | I3: Close [entry] | J3: Open | K3: Gap % | L3: Gap P/L | M3: P&L Var. from Slippage | N3: P/L per Trade | O3: P/L Total | P3: R per Trade | Q3: R Total | R3: Total Var Act v. Strat | S3: Trend | T3: Trend Y/N | U3: Entry Price: | V3: L / S | W3: Entry Shares | X3: Cost to Play | Y3: Exit Shares | Z3: Exit at Open or "Other" | AA3: P&L | AB3: Actual: MOC P / L | AC3: Exit Using MOC | AD3: Strategy: MOC P / L | AE3: Strategy: MOC R | AF3: Strategy P/L MOC Total | AG3: Var vs. Strategy | AH3: Exit Type | AI3: R per Trade | AJ3: R Total | AK3: P/L per Trade | AL3: P/L Total | AO3: Sw Trends MOC R | AP3: Total Sw Trends MOC R | AQ3: UP Trends MOC R | AR3: Total UP Trends MOC R | AS3: Dwn Trends MOC R | AT3: Total Dwn Trends MOC R | AU3: Sw Trends MOC P/L | AV3: Total Sw Trends MOC P/L | AW3: UP Trends MOC P/L | AX3: Total UP Trends MOC P/L | AY3: Dwn Trends MOC P/L | AZ3: Total Dwn Trends MOC P/L | BA3: Total MOC P/L | BC3: Gap Ups with trend | BD3: Gap Ups Against Trend | BE3: Gap Ups SW | BF3: Strategy Direction | BG3: Gap Downs with trend | BH3: Gap Dns Against Trend | BI3: Gap Downs SW | BK3: Exp 50-ma | BL3: Exp 25-ma | BM3: Overall Strategy Exp. | BO3: % of SW Gapping Up | BP3: % of DWN Gapping D | BQ3: % of UP Gapping Up | BR3: % Gapping Up | BS3: Long Wins | BT3: Long Losses | BU3: Short Wins | BV3: Short Losses | BW3: Playing Up Trends Long | BX3: Cumulative Playing Up Trends Long | BY3: Playing Down Trends Short | BZ3: Cumulative Playing Dwn Trends Short | CA3: Playing Sideways Trends Long | CB3: Cumulative Playing SW Trends Long | CC3: R, Playing Up Trends Long | CD3: Cumulative Playing Up Trends Long | CE3: R, Playing Down Trends Short | CF3: Cumulative Playing Dwn Trends Short | CG3: R, Playing Sideways Trends Long | CH3: Cumulative Playing SW Trends Long | CI3: Playing Up Trends Long | CJ3: Cumulative Playing Up Trends Long | CK3: Playing Down Trends Short | CL3: Cumulative Playing Dwn Trends Short | CM3: Playing Sideways Trends Long | CN3: Cumulative Playing SW Trends Long | CO3: TOTAL of Three Pillars | CP3: Playing Up Trends Long | CQ3: Cumulative Playing Up Trends Long | CR3: Playing Down Trends Short | CS3: Cumulative Playing Dwn Trends Short | CT3: Playing Sideways Trends Long | CU3: Cumulative Playing SW Trends Long | CV3: TOTAL of Three Pillars | CW3: Playing Up Trends Long | CX3: Cumulative Playing Up Trends Long | CY3: Playing Down Trends Short | CZ3: Cumulative Playing Dwn Trends Short | DA3: Playing Sideways Trends Long | DB3: Cumulative Playing SW Trends Long | DC3: TOTAL of Three Pillars | DD3: Playing Up Trends Long | DE3: Cumulative Playing Up Trends Long | DF3: Playing Down Trends Short | DG3: Cumulative Playing Dwn Trends Short | DH3: Playing Sideways Trends Long | DI3: Cumulative Playing SW Trends Long | DJ3: TOTAL of Three Pillars | DK3: Playing Up Trends Long | DL3: Cumulative Playing Up Trends Long | DM3: Playing Down Trends Short | DN3: Cumulative Playing Dwn Trends Short | DO3: Playing Sideways Trends Long | DP3: Cumulative Playing SW Trends Long | DQ3: TOTAL of Three Pillars | DR3: Playing Up Trends Long | DS3: Cumulative Playing Up Trends Long | DT3: Playing Down Trends Short | DU3: Cumulative Playing Dwn Trends Short | DV3: Playing Sideways Trends Long | DW3: Cumulative Playing SW Trends Long | DX3: TOTAL of Three Pillars | DY3: Playing Up Trends Long | DZ3: Cumulative Playing Up Trends Long | EA3: Playing Down Trends Short | EB3: Cumulative Playing Dwn Trends Short | EC3: Playing Sideways Trends Long | ED3: Cumulative Playing SW Trends Long | EE3: TOTAL of Three Pillars | EF3: Playing Up Trends Long | EG3: Cumulative Playing Up Trends Long | EH3: Playing Down Trends Short | EI3: Cumulative Playing Dwn Trends Short | EJ3: Playing Sideways Trends Long | EK3: Cumulative Playing SW Trends Long | EL3: TOTAL of Three Pillars | EM3: Playing Up Trends Long | EN3: Cumulative Playing Up Trends Long | EO3: Playing Down Trends Short | EP3: Cumulative Playing Dwn Trends Short | EQ3: Playing Sideways Trends Long | ER3: Cumulative Playing SW Trends Long | ES3: TOTAL of Three Pillars | ET3: Playing Up Trends Long | EU3: Cumulative Playing Up Trends Long | EV3: Playing Down Trends Short | EW3: Cumulative Playing Dwn Trends Short | EX3: Playing Sideways Trends Long | EY3: Cumulative Playing SW Trends Long | EZ3: TOTAL of Three Pillars | FA3: Playing Up Trends Long | FB3: Cumulative Playing Up Trends Long | FC3: Playing Down Trends Short | FD3: Cumulative Playing Dwn Trends Short | FE3: Playing Sideways Trends Long | FF3: Cumulative Playing SW Trends Long | FG3: TOTAL of Three Pillars | FH3: Playing Up Trends Long | FI3: Cumulative Playing Up Trends Long | FJ3: Playing Down Trends Short | FK3: Cumulative Playing Dwn Trends Short | FL3: Playing Sideways Trends Long | FM3: Cumulative Playing SW Trends Long | FN3: TOTAL of Three Pillars | FO3: Playing Up Trends Long | FP3: Cumulative Playing Up Trends Long | FQ3: Playing Down Trends Short | FR3: Cumulative Playing Dwn Trends Short | FS3: Playing Sideways Trends Long | FT3: Cumulative Playing SW Trends Long | FU3: TOTAL of Three Pillars | FV3: Playing Up Trends Long | FW3: Cumulative Playing Up Trends Long | FX3: Playing Down Trends Short | FY3: Cumulative Playing Dwn Trends Short | FZ3: Playing Sideways Trends Long | GA3: Cumulative Playing SW Trends Long | GB3: TOTAL of Three Pillars | GC3: Playing Up Trends Long | GD3: Cumulative Playing Up Trends Long | GE3: Playing Down Trends Short | GF3: Cumulative Playing Dwn Trends Short | GG3: Playing Sideways Trends Long | GH3: Cumulative Playing SW Trends Long | GI3: TOTAL of Three Pillars | GJ3: Playing Up Trends Long | GK3: Cumulative Playing Up Trends Long | GL3: Playing Down Trends Short | GM3: Cumulative Playing Dwn Trends Short | GN3: Playing Sideways Trends Long | GO3: Cumulative Playing SW Trends Long | GP3: TOTAL of Three Pillars | GS3: R per Trade | GT3: R Total | GU3: R per Trade Up | GV3: R Total Up Trends | GW3: R per Trade SW | GX3: R Total SW Trends | GY3: R per Trade Dwn | GZ3: R Total Dwn Trends | HA3: R per Trade | HB3: R Total | HC3: R per Trade Up | HD3: R Total Up Trends | HE3: R per Trade SW | HF3: R Total SW Trends | HG3: R per Trade Dwn | HH3: R Total Dwn Trends | HI3: R Dwn per Trade MOC | HJ3: R Dwn MOC Total | HK3: R Dwn per Trade MOC | HL3: R Dwn MOC Total | HM3: R per Trade MOC | HN3: R MOC Total | HO3: R Dwn per Trade MOC | HP3: R Dwn MOC Total | HQ3: R per Trade MOC | HR3: R MOC Total | HS3: R Dwn per Trade MOC | HT3: R Dwn MOC Total | HU3: R per Trade MOC | HV3: R MOC Total
